Workbook
Name ACE: Listes!$K$4:$K$6
Name CA: Listes!$L$4:$L$7
Name CE: Listes!$K$4:$K$6
Name CQ: Listes!$O$4:$O$9
Name FONCTION: Listes!$F$3:$F$18
Name GS: Listes!$P$4:$P$9
Name MA: Listes!$J$4:$J$8
Name OP: Listes!$I$4:$I$9
Name REX: Listes!$N$4:$N$6
Name RR: Listes!$M$4:$M$6
Name SOCIETE: Listes!$U$2:$U$5
Name STATUT: Listes!$X$2:$X$9

Sheet Pilotage effectif
K2: ="S"&WEEKNUM(K3) -> S24 | R2: ="S"&WEEKNUM(R3) -> S25 | Y2: ="S"&WEEKNUM(Y3) -> S26 | AF2: ="S"&WEEKNUM(AF3) -> S27 | AM2: ="S"&WEEKNUM(AM3) -> S28 | AT2: ="S"&WEEKNUM(AT3) -> S29 | BA2: ="S"&WEEKNUM(BA3) -> S30 | BH2: ="S"&WEEKNUM(BH3) -> S31 | BO2: ="S"&WEEKNUM(BO3) -> S32 | BV2: ="S"&WEEKNUM(BV3) -> S33 | CC2: ="S"&WEEKNUM(CC3) -> S34 | CJ2: ="S"&WEEKNUM(CJ3) -> S35 | CQ2: ="S"&WEEKNUM(CQ3) -> S36 | CX2: ="S"&WEEKNUM(CX3) -> S37 | DE2: ="S"&WEEKNUM(DE3) -> S38 | DL2: ="S"&WEEKNUM(DL3) -> S39 | DS2: ="S"&WEEKNUM(DS3) -> S40 | DZ2: ="S"&WEEKNUM(DZ3) -> S41 | EG2: ="S"&WEEKNUM(EG3) -> S42 | EN2: ="S"&WEEKNUM(EN3) -> S43 | EU2: ="S"&WEEKNUM(EU3) -> S44 | FB2: ="S"&WEEKNUM(FB3) -> S45 | FI2: ="S"&WEEKNUM(FI3) -> S46 | FP2: ="S"&WEEKNUM(FP3) -> S47 | FW2: ="S"&WEEKNUM(FW3) -> S48 | GD2: ="S"&WEEKNUM(GD3) -> S49 | GK2: ="S"&WEEKNUM(GK3) -> S50 | GR2: ="S"&WEEKNUM(GR3) -> S51 | GY2: ="S"&WEEKNUM(GY3) -> S52
K3: 45453 | L3: 45454 | M3: 45455 | N3: 45456 | O3: 45457 | P3: 45458 | Q3: 45459 | R3: 45460 | S3: 45461 | T3: 45462 | U3: 45463 | V3: 45464 | W3: 45465 | X3: 45466 | Y3: 45467 | Z3: 45468 | AA3: 45469 | AB3: 45470 | AC3: 45471 | AD3: 45472 | AE3: 45473 | AF3: 45474 | AG3: 45475 | AH3: 45476 | AI3: 45477 | AJ3: 45478 | AK3: 45479 | AL3: 45480 | AM3: 45481 | AN3: 45482 | AO3: 45483 | AP3: 45484 | AQ3: 45485 | AR3: 45486 | AS3: 45487 | AT3: 45488 | AU3: 45489 | AV3: 45490 | AW3: 45491 | AX3: 45492 | AY3: 45493 | AZ3: 45494 | BA3: 45495 | BB3: 45496 | BC3: 45497 | BD3: 45498 | BE3: 45499 | BF3: 45500 | BG3: 45501 | BH3: 45502 | BI3: 45503 | BJ3: 45504 | BK3: 45505 | BL3: 45506 | BM3: 45507 | BN3: 45508 | BO3: 45509 | BP3: 45510 | BQ3: 45511 | BR3: 45512 | BS3: 45513 | BT3: 45514 | BU3: 45515 | BV3: 45516 | BW3: 45517 | BX3: 45518 | BY3: 45519 | BZ3: 45520 | CA3: 45521 | CB3: 45522 | CC3: 45523 | CD3: 45524 | CE3: 45525 | CF3: 45526 | CG3: 45527 | CH3: 45528 | CI3: 45529 | CJ3: 45530 | CK3: 45531 | CL3: 45532 | CM3: 45533 | CN3: 45534 | CO3: 45535 | CP3: 45536 | CQ3: 45537 | CR3: 45538 | CS3: 45539 | CT3: 45540 | CU3: 45541 | CV3: 45542 | CW3: 45543 | CX3: 45544 | CY3: 45545 | CZ3: 45546 | DA3: 45547 | DB3: 45548 | DC3: 45549 | DD3: 45550 | DE3: 45551 | DF3: 45552 | DG3: 45553 | DH3: 45554 | DI3: 45555 | DJ3: 45556 | DK3: 45557 | DL3: 45558 | DM3: 45559 | DN3: 45560 | DO3: 45561 | DP3: 45562 | DQ3: 45563 | DR3: 45564 | DS3: 45565 | DT3: 45566 | DU3: 45567 | DV3: 45568 | DW3: 45569 | DX3: 45570 | DY3: 45571 | DZ3: 45572 | EA3: 45573 | EB3: 45574 | EC3: 45575 | ED3: 45576 | EE3: 45577 | EF3: 45578 | EG3: 45579 | EH3: 45580 | EI3: 45581 | EJ3: 45582 | EK3: 45583 | EL3: 45584 | EM3: 45585 | EN3: 45586 | EO3: 45587 | EP3: 45588 | EQ3: 45589 | ER3: 45590 | ES3: 45591 | ET3: 45592 | EU3: 45593 | EV3: 45594 | EW3: 45595 | EX3: 45596 | EY3: 45597 | EZ3: 45598 | FA3: 45599 | FB3: 45600 | FC3: 45601 | FD3: 45602 | FE3: 45603 | FF3: 45604 | FG3: 45605 | FH3: 45606 | FI3: 45607 | FJ3: 45608 | FK3: 45609 | FL3: 45610 | FM3: 45611 | FN3: 45612 | FO3: 45613 | FP3: 45614 | FQ3: 45615 | FR3: 45616 | FS3: 45617 | FT3: 45618 | FU3: 45619 | FV3: 45620 | FW3: 45621 | FX3: 45622 | FY3: 45623 | FZ3: 45624 | GA3: 45625 | GB3: 45626 | GC3: 45627 | GD3: 45628 | GE3: 45629 | GF3: 45630 | GG3: 45631 | GH3: 45632 | GI3: 45633 | GJ3: 45634 | GK3: 45635 | GL3: 45636 | GM3: 45637 | GN3: 45638 | GO3: 45639 | GP3: 45640 | GQ3: 45641 | GR3: 45642 | GS3: 45643 | GT3: 45644 | GU3: 45645 | GV3: 45646 | GW3: 45647 | GX3: 45648 | GY3: 45649 | GZ3: 45650 | HA3: 45651 | HB3: 45652 | HC3: 45653 | HD3: 45654 | HE3: 45655
C4: BASE H | F4: SOCIETE | G4: STATUT | H4: FONCTION | I4: NOM | J4: PRENOM | K4: =TEXT(K3,"jjj.jj") -> lun.10 | L4: =TEXT(L3,"jjj.jj") -> mar.11 | M4: =TEXT(M3,"jjj.jj") -> mer.12 | N4: =TEXT(N3,"jjj.jj") -> jeu.13 | O4: =TEXT(O3,"jjj.jj") -> ven.14 | P4: =TEXT(P3,"jjj.jj") -> sam.15 | Q4: =TEXT(Q3,"jjj.jj") -> dim.16 | R4: =TEXT(R3,"jjj.jj") -> lun.17 | ... HE4: =TEXT(HE3,"jjj.jj") -> dim.29
B5: 107522 | C5: 35 | D5: X | E5: =B5&""&D5 -> 107522X | F5: 27O | G5: CDD | H5: CA | I5: FAUVEL | J5: MICKAELE | K5: A. | L5: P. | M5: P. | N5: P. | O5: P. | R5: P. | S5: P. | T5: P. | U5: P. | V5: P.
B6: 107804 | C6: 35 | D6: X | E6: =B6&""&D6 -> 107804X | F6: 27O | G6: CDD | H6: CA | I6: OUSSENI | J6: BAROUFOUDINE | K6: P. | L6: P. | M6: P. | N6: P. | O6: P. | R6: P. | S6: P. | T6: P. | U6: P. | V6: P.
C7: 35 | D7: x | E7: =B7&""&D7 -> x | F7: 27O | G7: CDD | H7: OP | I7: QUERELLE | J7: TEDDY | K7: P. | L7: P. | M7: P. | N7: P. | O7: P. | R7: P. | S7: P. | T7: P. | U7: P. | V7: P.
B8: 104224 | C8: 35 | D8: =IF(G8="","","X") -> X | E8: =B8&""&D8 -> 104224X | F8: 27O | G8: CDD | H8: OP | I8: SARTIAUX | J8: ANTHONY | K8: P. | L8: P. | M8: P. | N8: P. | O8: P. | R8: P. | S8: P. | T8: P. | U8: P. | V8: P.
B9: 35714 | C9: 35 | D9: =IF(G9="","","X") -> X | E9: =B9&""&D9 -> 35714X | F9: 27O | G9: CDD | H9: CA | I9: SERFATI | J9: KEVIN | K9: P. | L9: P. | M9: P. | N9: P. | O9: P. | R9: P. | S9: P. | T9: P. | U9: P. | V9: P.
B10: 101143 | C10: 35 | D10: =IF(G10="","","X") -> X | E10: =B10&""&D10 -> 101143X | F10: 27O | G10: CDI | H10: OP | I10: ACARD | J10: THIERRY | K10: P. | L10: P. | M10: P. | N10: P. | O10: P. | R10: P. | S10: P. | T10: P. | U10: P. | V10: P.
B11: 101276 | C11: 35 | D11: =IF(G11="","","X") -> X | E11: =B11&""&D11 -> 101276X | F11: 27O | G11: CDI | H11: CQ | I11: AUBRON | J11: CHARLENE | K11: P. | L11: ECH | M11: ECH | N11: P. | O11: P. | R11: P. | S11: P. | T11: P. | U11: P. | V11: P.
B12: 105076 | C12: 35 | D12: =IF(G12="","","X") -> X | E12: =B12&""&D12 -> 105076X | F12: 27O | G12: CDI | H12: REX | I12: BAUDOUIN | J12: VANESSA | K12: P. | L12: P. | M12: P. | N12: P. | O12: P. | R12: P. | S12: P. | T12: P. | U12: P. | V12: P.
B13: 59970 | C13: 35 | D13: =IF(G13="","","X") -> X | E13: =B13&""&D13 -> 59970X | F13: 27O | G13: CDI | H13: ADM | I13: BESNARD | J13: LAURA | K13: P. | L13: P. | M13: P. | N13: P. | O13: P. | R13: P. | S13: P. | T13: P. | U13: P. | V13: P.
B14: 72844 | C14: 35 | D14: =IF(G14="","","X") -> X | E14: =B14&""&D14 -> 72844X | F14: 27O | G14: CDI | H14: RR | I14: BESSIN | J14: TRISTANA | K14: P. | L14: P. | M14: P. | N14: P. | O14: P. | R14: P. | S14: P. | T14: P. | U14: P. | V14: P.
B15: 71355 | C15: 35 | D15: =IF(G15="","","X") -> X | E15: =B15&""&D15 -> 71355X | F15: 27O | G15: CDI | H15: CQ | I15: BOIRON | J15: ALEXIA | K15: P. | L15: P. | M15: P. | N15: P. | O15: P. | R15: P. | S15: P. | T15: P. | U15: P. | V15: P.
B16: 40688 | C16: 35 | D16: =IF(G16="","","X") -> X | E16: =B16&""&D16 -> 40688X | F16: 27O | G16: CDI | H16: OP | I16: BOTELLE | J16: SANDRA | K16: P. | L16: P. | M16: P. | N16: P. | O16: P. | R16: P. | S16: P. | T16: P. | U16: P. | V16: P.
B17: 105600 | C17: 35 | D17: =IF(G17="","","X") -> X | E17: =B17&""&D17 -> 105600X | F17: 27O | G17: CDI | H17: CA | I17: CARON | J17: RAYAN | K17: P. | L17: P. | M17: P. | N17: P. | O17: P. | R17: P. | S17: P. | T17: P. | U17: P. | V17: P.
B18: 56995 | C18: 35 | D18: =IF(G18="","","X") -> X | E18: =B18&""&D18 -> 56995X | F18: 27O | G18: CDI | H18: OP | I18: CHEVALIER | J18: DEBORAH | K18: P. | L18: P. | M18: P. | N18: P. | O18: P. | R18: A. | S18: A. | T18: A. | U18: A. | V18: A.
B19: 104817 | C19: 35 | D19: =IF(G19="","","X") -> X | E19: =B19&""&D19 -> 104817X | F19: 27O | G19: CDI | H19: OP | I19: CLAUDE | J19: GUILLAUME | K19: P. | L19: P. | M19: P. | N19: P. | O19: P. | R19: P. | S19: P. | T19: P. | U19: P. | V19: P.
... B23: 50139 | C23: 39 | D23: =IF(G23="","","X") -> X | E23: =B23&""&D23 -> 50139X | F23: 27O | G23: CDI | H23: CA | I23: DUPARC | J23: CAROLINE | K23: P. | L23: P. | M23: P. | N23: P. | O23: P. | R23: P. | S23: P. | T23: P. | U23: P. | V23: P.
B24: I | C24: 35 | D24: X | E24: =B24&""&D24 -> IX | F24: 27O | G24: CDI | H24: CA | I24: DUPARC | J24: STEPHANE | K24: P. | L24: P. | M24: P. | N24: P. | O24: P. | R24: P. | S24: P. | T24: P. | U24: P. | V24: P.
B25: I | C25: 35 | D25: x | E25: =B25&""&D25 -> Ix | F25: 27O | G25: CDI | H25: CA | I25: EL AIYSSY | J25: ABDELHAMID | K25: P. | L25: P. | M25: P. | N25: P. | O25: P. | R25: P. | S25: P. | T25: P. | U25: P. | V25: P.
B26: I | C26: 35 | D26: X | E26: =B26&""&D26 -> IX | F26: 27O | G26: CDI | H26: CA | I26: GREMONT | J26: JORYS | K26: P. | L26: P. | M26: P. | N26: P. | O26: P. | R26: P. | S26: P. | T26: P. | U26: P. | V26: P.
B27: I | C27: 35 | D27: X | E27: =B27&""&D27 -> IX | F27: 27O | G27: CDI | H27: CA | I27: LEBIGRE | J27: DYLAN | K27: P. | L27: P. | M27: P. | N27: P. | O27: P. | R27: P. | S27: P. | T27: P. | U27: P. | V27: P.
B28: 101370 | C28: 35 | D28: X | E28: =B28&""&D28 -> 101370X | F28: 27O | G28: CDI | H28: OP | I28: LEFEBVRE | J28: JENNIFER | K28: P. | L28: P. | M28: P. | N28: P. | O28: P. | R28: P. | S28: P. | T28: P. | U28: P. | V28: P.
B29: 107722 | C29: 35 | D29: x | E29: =B29&""&D29 -> 107722x | F29: 27O | G29: CDI | H29: MA | I29: LEFEU | J29: JEAN LOUIS | K29: P. | L29: P. | M29: P. | N29: P. | O29: P. | R29: P. | S29: P. | T29: P. | U29: P. | V29: P.
B30: 106565 | C30: 35 | D30: X | E30: =B30&""&D30 -> 106565X | F30: 27O | G30: CDI | H30: OP | I30: LEROY | J30: MALVINA | K30: P. | L30: P. | M30: P. | N30: P. | O30: P. | R30: P. | S30: P. | T30: P. | U30: P. | V30: P.
B31: 107892 | C31: 35 | D31: X | E31: =B31&""&D31 -> 107892X | F31: 27O | G31: CDI | H31: CA | I31: MANGEANT | J31: MICKAEL | K31: P. | L31: P. | M31: P. | N31: P. | O31: P. | R31: P. | S31: P. | T31: P. | U31: P. | V31: P.
B32: 102329 | C32: 35 | D32: X | E32: =B32&""&D32 -> 102329X | F32: 27O | G32: CDI | H32: ADM | I32: MARIE | J32: MATHILDE | K32: P. | L32: P. | M32: P. | N32: P. | O32: P. | R32: P. | S32: P. | T32: P. | U32: P. | V32: P.
B33: 106564 | C33: 35 | D33: X | E33: =B33&""&D33 -> 106564X | F33: 27O | G33: CDI | H33: MA | I33: MOREAU | J33: ADRIEN | K33: P. | L33: P. | M33: P. | N33: P. | O33: P. | R33: P. | S33: P. | T33: P. | U33: P. | V33: P.
B34: 32116 | C34: 35 | D34: =IF(G34="","","X") -> X | E34: =B34&""&D34 -> 32116X | F34: 27O | G34: CDI | H34: OP | I34: MORISSE | J34: LAETITIA | K34: P. | L34: P. | M34: P. | N34: P. | O34: P. | R34: P. | S34: P. | T34: P. | U34: P. | V34: P.
B35: 101839 | C35: 35 | D35: =IF(G35="","","X") -> X | E35: =B35&""&D35 -> 101839X | F35: 27O | G35: CDI | H35: CA | I35: OUALI | J35: STEVE | K35: P. | L35: P. | M35: P. | N35: P. | O35: P. | R35: P. | S35: P. | T35: P. | U35: P. | V35: P.
B36: 56999 | C36: 35 | D36: =IF(G36="","","X") -> X | E36: =B36&""&D36 -> 56999X | F36: 27O | G36: CDI | H36: CA | I36: PELVILLAIN | J36: JESSY | K36: P. | L36: P. | M36: P. | N36: P. | O36: P. | R36: P. | S36: P. | T36: P. | U36: P. | V36: P.
B37: 36705 | C37: 35 | D37: =IF(G37="","","X") -> X | E37: =B37&""&D37 -> 36705X | F37: 27O | G37: CDI | H37: CA | I37: PLESSIS | J37: ERIC | K37: P. | L37: P. | M37: P. | N37: P. | O37: P. | R37: P. | S37: P. | T37: P. | U37: P. | V37: P.
B38: 33008 | C38: 35 | D38: =IF(G38="","","X") -> X | E38: =B38&""&D38 -> 33008X | F38: 27O | G38: CDI | H38: CA | I38: PREVOT | J38: ADELIN | K38: P. | L38: P. | M38: P. | N38: P. | O38: P. | R38: P. | S38: P. | T38: P. | U38: P. | V38: P.
B39: 33388 | C39: 35 | D39: =IF(G39="","","X") -> X | E39: =B39&""&D39 -> 33388X | F39: 27O | G39: CDI | H39: CA | I39: VINCENT | J39: ALEXIS | K39: P. | L39: P. | M39: P. | N39: P. | O39: P. | R39: P. | S39: P. | T39: P. | U39: P. | V39: P.
B40: 51530 | C40: 35 | D40: =IF(G40="","","X") -> X | E40: =B40&""&D40 -> 51530X | F40: 27O | G40: INTCRIT | H40: MA | I40: BECEL | J40: BASTIEN | K40: P. | L40: P. | M40: P. | N40: P. | O40: P. | R40: P. | S40: P. | T40: P. | U40: P. | V40: P.
B41: 105536 | C41: 35 | D41: X | E41: =B41&""&D41 -> 105536X | F41: 27O | G41: INTCRIT | H41: MA | I41: CHAPELLE | J41: ANDRE | K41: P. | L41: P. | M41: P. | N41: P. | O41: P. | R41: P. | S41: P. | T41: P. | U41: P. | V41: P.
B42: 71336 | C42: 35 | D42: =IF(G42="","","X") -> X | E42: =B42&""&D42 -> 71336X | F42: 27O | G42: INTCRIT | H42: OP | I42: COFFARD | J42: ANTHONY | K42: P. | L42: P. | M42: P. | N42: P. | O42: P. | R42: P. | S42: P. | T42: P. | U42: P. | V42: P.
B43: 34246 | C43: 35 | D43: =IF(G43="","","X") -> X | E43: =B43&""&D43 -> 34246X | F43: 27O | G43: INTCRIT | H43: MA | I43: FERREIRA SOARES | J43: SYLVAIN | K43: P. | L43: P. | M43: P. | N43: P. | O43: P. | R43: P. | S43: P. | T43: P. | U43: P. | V43: P.
B44: 34254 | C44: 35 | D44: =IF(G44="","","X") -> X | E44: =B44&""&D44 -> 34254X | F44: 27O | G44: INTCRIT | H44: MA | I44: HURAY | J44: HERVE | K44: P. | L44: P. | M44: P. | N44: P. | O44: P. | R44: P. | S44: P. | T44: P. | U44: P. | V44: P.
...

Sheet Feuil1 (2)
B3: MATRICULE | C3: BASE H | F3: SOCIETE | G3: STATUT | H3: FONCTION | I3: NOM | J3: PRENOM | K3: LUNDI | L3: MARDI | M3: MERCREDI | N3: JEUDI | O3: VENDREDI | Q3: STE | R3: CADENCE | S3: Hrs dispo | T3: Pcs théo | V3: STE | W3: EFFECTIF
B4: 107522 | C4: 35 | D4: X | E4: =B4&""&D4 -> 107522X | F4: PA | G4: CDD | H4: OP | I4: BOISARD | J4: MANON | K4: PA1ETIQ | L4: PA1ETIQ | M4: FERIE | N4: PA1ETIQ | O4: PA1ETIQ | Q4: PA1 | R4: 350 | V4: PA1
B5: 107804 | C5: 35 | D5: X | E5: =B5&""&D5 -> 107804X | F5: PA | G5: CDD | H5: OP | I5: GUINAND | J5: AUDREY | K5: PA1ETIQ | L5: PA1ETIQ | M5: FERIE | N5: PA1ETIQ | O5: PA1ETIQ | Q5: PA2 | R5: 350 | V5: PA2
C6: 35 | D6: x | E6: =B6&""&D6 -> x | F6: PA | G6: CDD | H6: OP | I6: MECHERI | J6: OCEANE | K6: PA1ETIQ | L6: PA1ETIQ | M6: FERIE | N6: PA1ETIQ | O6: PA1ETIQ | Q6: CFP1 | R6: 350 | V6: CFP1
B7: 104224 | C7: 35 | D7: =IF(G7="","","X") -> X | E7: =B7&""&D7 -> 104224X | F7: PA | G7: CDI | H7: OP | I7: CHAMBELLAN | J7: MAUD | K7: PA1ETIQ | L7: PA1ETIQ | M7: FERIE | N7: PA1ETIQ | O7: PA1ETIQ | Q7: CFP2 | R7: 350 | V7: CFP2
B8: 35714 | C8: 35 | D8: =IF(G8="","","X") -> X | E8: =B8&""&D8 -> 35714X | F8: PA | G8: CDI | H8: OP | I8: COUTURE | J8: LUCIE | K8: PA1ETIQ | L8: PA2ETIQ | M8: FERIE | N8: PA1ETIQ | O8: PA1ETIQ | Q8: EUP1 | R8: 350 | V8: EUP1
B9: 101143 | C9: 35 | D9: =IF(G9="","","X") -> X | E9: =B9&""&D9 -> 101143X | F9: PA | G9: CDI | H9: OP | I9: COUTURIER | J9: CHLOE | K9: PA1ETIQ | L9: PA2ETIQ | M9: FERIE | N9: PA1ETIQ | O9: PA1ETIQ | Q9: EUP2 | R9: 350 | V9: EUP2
B10: 101276 | C10: 35 | D10: =IF(G10="","","X") -> X | E10: =B10&""&D10 -> 101276X | F10: PA | G10: CDI | H10: OP | I10: COUTURIER | J10: SONIA | K10: PA1ETIQ | L10: PA2ETIQ | M10: FERIE | N10: PA1ETIQ | O10: PA1ETIQ
B11: 105076 | C11: 35 | D11: =IF(G11="","","X") -> X | E11: =B11&""&D11 -> 105076X | F11: PA | G11: CDI | H11: OP | I11: DEHAIS | J11: ANTHONY | K11: PA2ETIQ | L11: PA2ETIQ | M11: FERIE | N11: PA1ETIQ | O11: PA1ETIQ
B12: 59970 | C12: 35 | D12: =IF(G12="","","X") -> X | E12: =B12&""&D12 -> 59970X | F12: PA | G12: CDI | H12: ACE | I12: FOUTREL | J12: STEPHANIE | K12: PA1ETIQ | L12: PA2ETIQ | M12: FERIE | N12: PA1ETIQ | O12: PA1ETIQ | Q12: STE | R12: Nb pcs | S12: Hrs affecté | T12: Delta
B13: 72844 | C13: 35 | D13: =IF(G13="","","X") -> X | E13: =B13&""&D13 -> 72844X | F13: PA | G13: CDI | H13: OP | I13: GLINEL | J13: ANGELIQUE | K13: PA1ETIQ | L13: PA2ETIQ | M13: FERIE | N13: PA1ETIQ | O13: PA1ETIQ | Q13: PA1
B14: 71355 | C14: 35 | D14: =IF(G14="","","X") -> X | E14: =B14&""&D14 -> 71355X | F14: PA | G14: CDI | H14: ACE | I14: LAFOSSE | J14: OLIVIER | K14: ENCA PA | L14: ENCA PA | M14: FERIE | N14: ENCA PA | O14: ENCA PA | Q14: PA2
B15: 40688 | C15: 35 | D15: =IF(G15="","","X") -> X | E15: =B15&""&D15 -> 40688X | F15: PA | G15: CDI | H15: OP | I15: LEFRANCOIS | J15: SANDIE | K15: PA2ETIQ | L15: PA2ETIQ | M15: FERIE | N15: PA2ETIQ | O15: PA2ETIQ | Q15: CFP1
B16: 105600 | C16: 35 | D16: =IF(G16="","","X") -> X | E16: =B16&""&D16 -> 105600X | F16: PA | G16: CDI | H16: OP | I16: LENORMAND | J16: ANITA | K16: PA2ETIQ | L16: PA2ETIQ | M16: FERIE | N16: PA2ETIQ | O16: PA2ETIQ | Q16: CFP2
B17: 56995 | C17: 35 | D17: =IF(G17="","","X") -> X | E17: =B17&""&D17 -> 56995X | F17: PA | G17: CDI | H17: OP | I17: LESEIGNEUR | J17: DELPHINE | K17: PA2ETIQ | L17: PA2ETIQ | M17: FERIE | N17: PA2ETIQ | O17: PA2ETIQ | Q17: EUP1
B18: 104817 | C18: 35 | D18: =IF(G18="","","X") -> X | E18: =B18&""&D18 -> 104817X | F18: PA | G18: CDI | H18: OP | I18: MORCAMP | J18: FLAVIE | K18: PA2ETIQ | L18: PA2ETIQ | M18: FERIE | N18: PA2ETIQ | O18: PA2ETIQ | Q18: EUP2
B19: 27609 | C19: 35 | D19: =IF(G19="","","X") -> X | E19: =B19&""&D19 -> 27609X | F19: PA | G19: CDI | H19: OP | I19: PERNEL | J19: LUCIE | K19: PA2ETIQ | L19: PA2ETIQ | M19: FERIE | N19: PA2ETIQ | O19: PA2ETIQ
B20: 105254 | C20: 35 | D20: =IF(G20="","","X") -> X | E20: =B20&""&D20 -> 105254X | F20: PA | G20: CDI | H20: OP | I20: TESSIER | J20: PERRINE | K20: PA2ETIQ | L20: PA2ETIQ | M20: FERIE | N20: PA2ETIQ | O20: PA2ETIQ
B21: 104227 | C21: 35 | D21: =IF(G21="","","X") -> X | E21: =B21&""&D21 -> 104227X | F21: PA | G21: CDI | H21: ACE | I21: TUVACHE | J21: SOPHIE | K21: ENCA PA | L21: ENCA PA | M21: FERIE | N21: ENCA PA | O21: ENCA PA | Q21: POSTE | R21: LUNDI | S21: MARDI | T21: MERCREDI | U21: JEUDI | V21: VENDREDI
B22: 50139 | C22: 39 | D22: =IF(G22="","","X") -> X | E22: =B22&""&D22 -> 50139X | F22: PA | G22: COG | H22: CE | I22: NIBREU | J22: CLYDE | K22: ENCA PA | L22: ENCA PA | M22: FERIE | N22: ENCA PA | O22: ENCA PA | Q22: VRAC | R22: 12 | S22: 12 | T22: 12 | U22: 12 | V22: 12 | W22: BESOIN
B23: I | C23: 35 | D23: X | E23: =B23&""&D23 -> IX | F23: PA | G23: INTADE | H23: OP | I23: EBANDA | J23: GILBERT | K23: A | L23: A | M23: FERIE | N23: A | O23: A | W23: AFFECTE
B24: I | C24: 35 | D24: x | E24: =B24&""&D24 -> Ix | F24: PA | G24: INTADE | H24: MA | I24: HENRY | J24: ASHLEY | K24: A | L24: A | M24: FERIE | N24: A | O24: A | Q24: CAR | R24: 6 | S24: 6 | T24: 6 | U24: 6 | V24: 6
B25: I | C25: 35 | D25: X | E25: =B25&""&D25 -> IX | F25: PA | G25: INTCRIT | H25: OP | I25: BRUMEAU | J25: CYPRIEN | K25: A | L25: A | M25: FERIE | N25: A | O25: A
B26: I | C26: 35 | D26: X | E26: =B26&""&D26 -> IX | F26: PA | G26: INTCRIT | H26: OP | I26: MILLOT | J26: AURELIE | K26: A | L26: A | M26: FERIE | N26: A | O26: A | Q26: ENCA PA | R26: 3 | S26: 3 | T26: 3 | U26: 3 | V26: 3
B27: 101370 | C27: 35 | D27: X | E27: =B27&""&D27 -> 101370X | F27: EUP | G27: CDD | H27: OP | I27: BUNEL | J27: SYLVIE | K27: EUP1ETIQ | L27: EUP1ETIQ | M27: FERIE | N27: EUP1ETIQ | O27: EUP1ETIQ
B28: 107722 | C28: 35 | D28: x | E28: =B28&""&D28 -> 107722x | F28: EUP | G28: CDD | H28: OP | I28: CHEVALIER | J28: SABRINA | K28: EUP1ETIQ | L28: EUP1ETIQ | M28: FERIE | N28: EUP1ETIQ | O28: EUP1ETIQ | Q28: ENCA CFP | R28: 3 | S28: 3 | T28: 3 | U28: 3 | V28: 3
B29: 106565 | C29: 35 | D29: X | E29: =B29&""&D29 -> 106565X | F29: EUP | G29: CDD | H29: OP | I29: CHEVALLIER | J29: JUSTINE | K29: EUP1ETIQ | L29: EUP1ETIQ | M29: FERIE | N29: EUP1ETIQ | O29: EUP1ETIQ
B30: 107892 | C30: 35 | D30: X | E30: =B30&""&D30 -> 107892X | F30: EUP | G30: CDD | H30: OP | I30: MORAINE | J30: MANON | K30: EUP1ETIQ | L30: EUP1ETIQ | M30: FERIE | N30: EUP1ETIQ | O30: EUP1ETIQ | Q30: ENCA EUP | R30: 3 | S30: 3 | T30: 3 | U30: 3 | V30: 3
B31: 102329 | C31: 35 | D31: X | E31: =B31&""&D31 -> 102329X | F31: EUP | G31: CDD | H31: OP | I31: PAPORE | J31: MARIE | K31: EUP1ETIQ | L31: EUP1ETIQ | M31: FERIE | N31: EUP1ETIQ | O31: EUP1ETIQ
B32: 106564 | C32: 35 | D32: X | E32: =B32&""&D32 -> 106564X | F32: EUP | G32: CDD | H32: OP | I32: WARNAULT | J32: STEPHANIE | K32: EUP1ETIQ | L32: EUP1ETIQ | M32: FERIE | N32: EUP1ETIQ | O32: EUP1ETIQ | Q32: FILM | R32: 5 | S32: 5 | T32: 5 | U32: 5 | V32: 5
B33: 32116 | C33: 35 | D33: =IF(G33="","","X") -> X | E33: =B33&""&D33 -> 32116X | F33: EUP | G33: CDI | H33: OP | I33: BABIN | J33: MYRIAM | K33: EUP1ETIQ | L33: EUP1ETIQ | M33: FERIE | N33: EUP1ETIQ | O33: EUP1ETIQ
B34: 101839 | C34: 35 | D34: =IF(G34="","","X") -> X | E34: =B34&""&D34 -> 101839X | F34: EUP | G34: CDI | H34: OP | I34: BLOT | J34: SOPHIE | K34: EUP1ETIQ | L34: EUP1ETIQ | M34: FERIE | N34: EUP1ETIQ | O34: EUP1ETIQ | Q34: ECHANT | R34: 3 | S34: 3 | T34: 3 | U34: 3 | V34: 3
B35: 56999 | C35: 35 | D35: =IF(G35="","","X") -> X | E35: =B35&""&D35 -> 56999X | F35: EUP | G35: CDI | H35: OP | I35: COLOMBEL | J35: LUCIE | K35: EUP1ETIQ | L35: EUP1ETIQ | M35: FERIE | N35: EUP1ETIQ | O35: EUP1ETIQ
B36: 36705 | C36: 35 | D36: =IF(G36="","","X") -> X | E36: =B36&""&D36 -> 36705X | F36: EUP | G36: CDI | H36: OP | I36: COUTURIER | J36: DORINE | K36: EUP1ETIQ | L36: EUP1ETIQ | M36: FERIE | N36: EUP1ETIQ | O36: EUP1ETIQ | Q36: FI | R36: 1 | S36: 1 | T36: 1 | U36: 1 | V36: 1
B37: 33008 | C37: 35 | D37: =IF(G37="","","X") -> X | E37: =B37&""&D37 -> 33008X | F37: EUP | G37: CDI | H37: OP | I37: DELARUE | J37: CLAUDINE | K37: EUP1ETIQ | L37: EUP1ETIQ | M37: FERIE | N37: EUP1ETIQ | O37: EUP1ETIQ
B38: 33388 | C38: 35 | D38: =IF(G38="","","X") -> X | E38: =B38&""&D38 -> 33388X | F38: EUP | G38: CDI | H38: OP | I38: DELAUNAY | J38: MARIE-FRANCE | K38: EUP1ETIQ | L38: EUP1ETIQ | M38: FERIE | N38: EUP1ETIQ | O38: EUP1ETIQ | Q38: PTRI | R38: 2 | S38: 2 | T38: 2 | U38: 2 | V38: 2
B39: 51530 | C39: 35 | D39: =IF(G39="","","X") -> X | E39: =B39&""&D39 -> 51530X | F39: EUP | G39: CDI | H39: OP | I39: DEMOUSTIER | J39: LYNDA-STEPHANIE | K39: EUP1ETIQ | L39: EUP1ETIQ | M39: FERIE | N39: EUP1ETIQ | O39: EUP1ETIQ
B40: 105536 | C40: 35 | D40: X | E40: =B40&""&D40 -> 105536X | F40: EUP | G40: CDI | H40: OP | I40: DUMONTIER | J40: MARINE | K40: EUP1ETIQ | L40: EUP1ETIQ | M40: FERIE | N40: EUP1ETIQ | O40: EUP1ETIQ | Q40: ETIQ | R40: 1 | S40: 1 | T40: 1 | U40: 1 | V40: 1
B41: 71336 | C41: 35 | D41: =IF(G41="","","X") -> X | E41: =B41&""&D41 -> 71336X | F41: EUP | G41: CDI | H41: OP | I41: DUPEROUX | J41: CHARLENE | K41: EUP1ETIQ | L41: EUP1ETIQ | M41: FERIE | N41: EUP1ETIQ | O41: EUP1ETIQ
B42: 34246 | C42: 35 | D42: =IF(G42="","","X") -> X | E42: =B42&""&D42 -> 34246X | F42: EUP | G42: CDI | H42: ACE | I42: FRESTEL | J42: SOPHIE | K42: EUP2ETIQ | L42: EUP2ETIQ | M42: FERIE | N42: EUP1ETIQ | O42: EUP2ETIQ
...

Sheet TDB V2
F2: S01 | M2: ="S"&WEEKNUM(M33) -> S2 | T2: ="S"&WEEKNUM(T33) -> S3 | AA2: ="S"&WEEKNUM(AA33) -> S4 | AH2: ="S"&WEEKNUM(AH33) -> S5 | AO2: ="S"&WEEKNUM(AO33) -> S6 | AV2: ="S"&WEEKNUM(AV33) -> S7 | BC2: ="S"&WEEKNUM(BC33) -> S8 | BJ2: ="S"&WEEKNUM(BJ33) -> S9 | BQ2: ="S"&WEEKNUM(BQ33) -> S10 | BX2: ="S"&WEEKNUM(BX33) -> S11 | CE2: ="S"&WEEKNUM(CE33) -> S12 | CL2: ="S"&WEEKNUM(CL33) -> S13 | CS2: ="S"&WEEKNUM(CS33) -> S14 | CZ2: ="S"&WEEKNUM(CZ33) -> S15 | DG2: ="S"&WEEKNUM(DG33) -> S16 | DN2: ="S"&WEEKNUM(DN33) -> S17 | DU2: ="S"&WEEKNUM(DU33) -> S18 | EB2: ="S"&WEEKNUM(EB33) -> S19 | EI2: ="S"&WEEKNUM(EI33) -> S20 | EP2: ="S"&WEEKNUM(EP33) -> S21 | EW2: ="S"&WEEKNUM(EW33) -> S22 | FD2: ="S"&WEEKNUM(FD33) -> S23 | FK2: ="S"&WEEKNUM(FK33) -> S24 | FR2: ="S"&WEEKNUM(FR33) -> S25 | FY2: ="S"&WEEKNUM(FY33) -> S26 | GF2: ="S"&WEEKNUM(GF33) -> S27 | GM2: ="S"&WEEKNUM(GM33) -> S28 | GT2: ="S"&WEEKNUM(GT33) -> S29 | HA2: ="S"&WEEKNUM(HA33) -> S30 | HH2: ="S"&WEEKNUM(HH33) -> S31 | HO2: ="S"&WEEKNUM(HO33) -> S32 | HV2: ="S"&WEEKNUM(HV33) -> S33 | IC2: ="S"&WEEKNUM(IC33) -> S34 | IJ2: ="S"&WEEKNUM(IJ33) -> S35 | IQ2: ="S"&WEEKNUM(IQ33) -> S36 | IX2: ="S"&WEEKNUM(IX33) -> S37 | JE2: ="S"&WEEKNUM(JE33) -> S38 | JL2: ="S"&WEEKNUM(JL33) -> S39 | JS2: ="S"&WEEKNUM(JS33) -> S40 | JZ2: ="S"&WEEKNUM(JZ33) -> S41 | KG2: ="S"&WEEKNUM(KG33) -> S42 | KN2: ="S"&WEEKNUM(KN33) -> S43 | KU2: ="S"&WEEKNUM(KU33) -> S44 | LB2: ="S"&WEEKNUM(LB33) -> S45 | LI2: ="S"&WEEKNUM(LI33) -> S46 | LP2: ="S"&WEEKNUM(LP33) -> S47 | LW2: ="S"&WEEKNUM(LW33) -> S48 | MD2: ="S"&WEEKNUM(MD33) -> S49 | MK2: ="S"&WEEKNUM(MK33) -> S50 | MR2: ="S"&WEEKNUM(MR33) -> S51 | MY2: ="S"&WEEKNUM(MY33) -> S52 | NF2: ="S"&WEEKNUM(NF33) -> S53 | NM2: ="S"&WEEKNUM(NM33) -> S2
F4: Prod. | G4: Valeur obj. | I4: H. prod | J4: P.U | K4: Val théo | M4: Prod. | N4: Valeur obj. | P4: H. prod | Q4: P.U | R4: Val théo | T4: Prod. | U4: Valeur obj. | W4: H. prod | X4: P.U | Y4: Val théo | AA4: Prod. | AB4: Valeur obj. | AD4: H. prod | AE4: P.U | AF4: Val théo | AH4: Prod. | AI4: Valeur obj. | AK4: H. prod | AL4: P.U | AM4: Val théo | AO4: Prod. | AP4: Valeur obj. | AR4: H. prod | AS4: P.U | AT4: Val théo | AV4: Prod. | AW4: Valeur obj. | AY4: H. prod | AZ4: P.U | BA4: Val théo | BC4: Prod. | BD4: Valeur obj. | BF4: H. prod | BG4: P.U | BH4: Val théo | BJ4: Prod. | BK4: Valeur obj. | BM4: H. prod | BN4: P.U | BO4: Val théo | BQ4: Prod. | BR4: Valeur obj. | BT4: H. prod | BU4: P.U | BV4: Val théo | BX4: Prod. | BY4: Valeur obj. | CA4: H. prod | CB4: P.U | CC4: Val théo | CE4: Prod. | CF4: Valeur obj. | CH4: H. prod | CI4: P.U | CJ4: Val théo | CL4: Prod. | CM4: Valeur obj. | CO4: H. prod | CP4: P.U | CQ4: Val théo | CS4: Prod. | CT4: Valeur obj. | CV4: H. prod | CW4: P.U | CX4: Val théo | CZ4: Prod. | DA4: Valeur obj. | DC4: H. prod | DD4: P.U | DE4: Val théo | DG4: Prod. | DH4: Valeur obj. | DJ4: H. prod | DK4: P.U | DL4: Val théo | DN4: Prod. | DO4: Valeur obj. | DQ4: H. prod | DR4: P.U | DS4: Val théo | DU4: Prod. | DV4: Valeur obj. | DX4: H. prod | DY4: P.U | DZ4: Val théo | EB4: Prod. | EC4: Valeur obj. | EE4: H. prod | EF4: P.U | EG4: Val théo | EI4: Prod. | EJ4: Valeur obj. | EL4: H. prod | EM4: P.U | EN4: Val théo | EP4: Prod. | EQ4: Valeur obj. | ES4: H. prod | ET4: P.U | EU4: Val théo | EW4: Prod. | EX4: Valeur obj. | EZ4: H. prod | FA4: P.U | FB4: Val théo | FD4: Prod. | FE4: Valeur obj. | FG4: H. prod | FH4: P.U | FI4: Val théo | FK4: Prod. | FL4: Valeur obj. | FN4: H. prod | FO4: P.U | FP4: Val théo | FR4: Prod. | FS4: Valeur obj. | FU4: H. prod | FV4: P.U | FW4: Val théo | FY4: Prod. | FZ4: Valeur obj. | GB4: H. prod | GC4: P.U | GD4: Val théo | GF4: Prod. | GG4: Valeur obj. | GI4: H. prod | GJ4: P.U | GK4: Val théo | GM4: Prod. | GN4: Valeur obj. | GP4: H. prod | GQ4: P.U | GR4: Val théo | GT4: Prod. | GU4: Valeur obj. | GW4: H. prod | GX4: P.U | GY4: Val théo | HA4: Prod. | HB4: Valeur obj. | HD4: H. prod | HE4: P.U | HF4: Val théo | HH4: Prod. | HI4: Valeur obj. | HK4: H. prod | HL4: P.U | HM4: Val théo | HO4: Prod. | HP4: Valeur obj. | HR4: H. prod | HS4: P.U | HT4: Val théo | HV4: Prod. | HW4: Valeur obj. | HY4: H. prod | HZ4: P.U | IA4: Val théo | IC4: Prod. | ID4: Valeur obj. | IF4: H. prod | IG4: P.U | IH4: Val théo | IJ4: Prod. | IK4: Valeur obj. | IM4: H. prod | IN4: P.U | IO4: Val théo | IQ4: Prod. | IR4: Valeur obj. | IT4: H. prod | IU4: P.U | IV4: Val théo | IX4: Prod. | IY4: Valeur obj. | JA4: H. prod | JB4: P.U | JC4: Val théo | JE4: Prod. | JF4: Valeur obj. | JH4: H. prod | JI4: P.U | JJ4: Val théo | JL4: Prod. | JM4: Valeur obj. | JO4: H. prod | JP4: P.U | JQ4: Val théo | JS4: Prod. | JT4: Valeur obj. | JV4: H. prod | JW4: P.U | JX4: Val théo | JZ4: Prod. | KA4: Valeur obj. | KC4: H. prod | KD4: P.U | KE4: Val théo | KG4: Prod. | KH4: Valeur obj. | KJ4: H. prod | KK4: P.U | KL4: Val théo | KN4: Prod. | KO4: Valeur obj. | KQ4: H. prod | KR4: P.U | KS4: Val théo | KU4: Prod. | KV4: Valeur obj. | KX4: H. prod | KY4: P.U | KZ4: Val théo | LB4: Prod. | LC4: Valeur obj. | LE4: H. prod | LF4: P.U | LG4: Val théo | LI4: Prod. | LJ4: Valeur obj. | LL4: H. prod | LM4: P.U | LN4: Val théo | LP4: Prod. | LQ4: Valeur obj. | LS4: H. prod | LT4: P.U | LU4: Val théo | LW4: Prod. | LX4: Valeur obj. | LZ4: H. prod | MA4: P.U | MB4: Val théo | MD4: Prod. | ME4: Valeur obj. | MG4: H. prod | MH4: P.U | MI4: Val théo | MK4: Prod. | ML4: Valeur obj. | MN4: H. prod | MO4: P.U | MP4: Val théo | MR4: Prod. | MS4: Valeur obj. | MU4: H. prod | MV4: P.U | MW4: Val théo | MY4: Prod. | MZ4: Valeur obj. | NB4: H. prod | NC4: P.U | ND4: Val théo | NF4: Prod. | NG4: Valeur obj. | NI4: H. prod | NJ4: P.U | NK4: Val théo | NM4: Prod. | NN4: Valeur obj. | NP4: H. prod | NQ4: P.U | NR4: Val théo
F5: 600 | G5: 2600000 | I5: =(G5/F5) -> 4333.3333 | J5: 3 | K5: =I7*J5*F9 -> 3707550 | M5: 600 | N5: 2600000 | P5: =(N5/M5) -> 4333.3333 | Q5: 3 | R5: =P7*Q5*M9 -> 3514896 | T5: 600 | U5: 3000000 | W5: =(U5/T5) -> 5000 | X5: 2.9 | Y5: =W7*X5*T9 -> 4194183 | AA5: 600 | AB5: 2600000 | AD5: =(AB5/AA5) -> 4333.3333 | AE5: 2.9 | AF5: =AD7*AE5*AA9 -> 3423087.5 | AH5: 600 | AI5: 2600000 | AK5: =(AI5/AH5) -> 4333.3333 | AL5: 2.9 | AM5: =AK7*AL5*AH9 -> 3351022.5 | AO5: 600 | AP5: 2600000 | AR5: =(AP5/AO5) -> 4333.3333 | AS5: 2.5 | AT5: =AR7*AS5*AO9 -> 3288187.5 | AV5: 600 | AW5: 2600000 | AY5: =(AW5/AV5) -> 4333.3333 | AZ5: 2.7 | BA5: =AY7*AZ5*AV9 -> 3146755.5 | BC5: 600 | BD5: 2600000 | BF5: =(BD5/BC5) -> 4333.3333 | BG5: 2.8 | BH5: =BF7*BG5*BC9 -> 3235470 | BJ5: 600 | BK5: 2600000 | BM5: =(BK5/BJ5) -> 4333.3333 | BN5: 3.2 | BO5: =BM7*BN5*BJ9 -> 3360000 | BQ5: 600 | BR5: 2200000 | BT5: =(BR5/BQ5) -> 3666.6667 | BU5: 2.7 | BV5: =BT7*BU5*BQ9 -> 2835000 | BX5: 600 | BY5: 2600000 | CA5: =(BY5/BX5) -> 4333.3333 | CB5: 2.8 | CC5: =CA7*CB5*BX9 -> 3073280 | CE5: 600 | CF5: 2600000 | CH5: =(CF5/CE5) -> 4333.3333 | CI5: 3.1 | CJ5: =CH7*CI5*CE9 -> 3194240 | CL5: 600 | CM5: 2600000 | CO5: =(CM5/CL5) -> 4333.3333 | CP5: 3.1 | CQ5: =CO7*CP5*CL9 -> 3314675 | CS5: 600 | CT5: 2600000 | CV5: =(CT5/CS5) -> 4333.3333 | CW5: 3 | CX5: =CV7*CW5*CS9 -> 3192000 | CZ5: 600 | DA5: 2600000 | DC5: =(DA5/CZ5) -> 4333.3333 | DD5: 2.9 | DE5: =DC7*DD5*CZ9 -> 2968672 | DG5: 600 | DH5: 2600000 | DJ5: =(DH5/DG5) -> 4333.3333 | DK5: 3.1 | DL5: =DJ7*DK5*DG9 -> 2821000 | DN5: 600 | DO5: 2100000 | DQ5: =(DO5/DN5) -> 3500 | DR5: 2.9 | DS5: =DQ7*DR5*DN9 -> 2599212 | DU5: 645 | DV5: 2160000 | DX5: =(DV5/DU5) -> 3348.8372 | DY5: 3.1 | DZ5: =DX7*DY5*DU9 -> 2722482 | EB5: 600 | EC5: 2800000 | EE5: =(EC5/EB5) -> 4666.6667 | EF5: 3 | EG5: =EE7*EF5*EB9 -> 2870280 | EI5: 600 | EJ5: 2600000 | EL5: =(EJ5/EI5) -> 4333.3333 | EM5: 3 | EN5: =EL7*EM5*EI9 -> 2989350 | EP5: 600 | EQ5: 2200000 | ES5: =(EQ5/EP5) -> 3666.6667 | ET5: 2.2 | EU5: =ES7*ET5*EP9 -> 2312310 | EW5: 600 | EX5: 2600000 | EZ5: =(EX5/EW5) -> 4333.3333 | FA5: 3 | FB5: =EZ7*FA5*EW9 -> 2945250 | FD5: 600 | FE5: 2600000 | FG5: =(FE5/FD5) -> 4333.3333 | FH5: 3.5 | FI5: =FG7*FH5*FD9 -> 3638250 | FK5: 600 | FL5: 2600000 | FN5: =(FL5/FK5) -> 4333.3333 | FO5: 3 | FP5: =FN7*FO5*FK9 -> 2808000 | FR5: 630 | FS5: 3000000 | FU5: =(FS5/FR5) -> 4761.9048 | FV5: 3 | FW5: =FU7*FV5*FR9 -> 3014550 | FY5: 630 | FZ5: 3000000 | GB5: =(FZ5/FY5) -> 4761.9048 | GC5: 3 | GD5: =GB7*GC5*FY9 -> 2936640 | GF5: 630 | GG5: 3000000 | GI5: =(GG5/GF5) -> 4761.9048 | GJ5: 3 | GK5: =GI7*GJ5*GF9 -> 2822400 | GM5: 630 | GN5: 3000000 | GP5: =(GN5/GM5) -> 4761.9048 | GQ5: 3 | GR5: =GP7*GQ5*GM9 -> 2755200 | GT5: 630 | GU5: 2600000 | GW5: =(GU5/GT5) -> 4126.9841 | GX5: 3 | GY5: =GW7*GX5*GT9 -> 2190720 | HA5: 630 | HB5: 3000000 | HD5: =(HB5/HA5) -> 4761.9048 | HE5: 3 | HF5: =HD7*HE5*HA9 -> 2520000 | HH5: 600 | HI5: 3000000 | HK5: =(HI5/HH5) -> 5000 | HL5: 3 | HM5: =HK7*HL5*HH9 -> 2545920 | HO5: 630 | HP5: 3000000 | HR5: =(HP5/HO5) -> 4761.9048 | HS5: 3 | HT5: =HR7*HS5*HO9 -> 2352000 | HV5: 630 | HW5: 3000000 | HY5: =(HW5/HV5) -> 4761.9048 | HZ5: 3 | IA5: =HY7*HZ5*HV9 -> 2452800 | IC5: 630 | ID5: 3000000 | IF5: =(ID5/IC5) -> 4761.9048 | IG5: 3 | IH5: =IF7*IG5*IC9 -> 2721600 | IJ5: 630 | IK5: 2200000 | IM5: =(IK5/IJ5) -> 3492.0635 | IN5: 3 | IO5: =IM7*IN5*IJ9 -> 2709000 | IQ5: 600 | IR5: 2600000 | IT5: =(IR5/IQ5) -> 4333.3333 | IU5: 3 | IV5: =IT7*IU5*IQ9 -> 2943360 | IX5: 600 | IY5: 2600000 | JA5: =(IY5/IX5) -> 4333.3333 | JB5: 3.1 | JC5: =JA7*JB5*IX9 -> 3124800 | JE5: 600 | JF5: 2600000 | JH5: =(JF5/JE5) -> 4333.3333 | JI5: 3.1 | JJ5: =JH7*JI5*JE9 -> 3632037.5 | JL5: 600 | JM5: 2600000 | JO5: =(JM5/JL5) -> 4333.3333 | JP5: 3 | JQ5: =JO7*JP5*JL9 -> 3595200 | JS5: 600 | JT5: 2600000 | JV5: =(JT5/JS5) -> 4333.3333 | JW5: 2.9 | JX5: =JV7*JW5*JS9 -> 3540320 | JZ5: 600 | KA5: 2600000 | KC5: =(KA5/JZ5) -> 4333.3333 | KD5: 3.1 | KE5: =KC7*KD5*JZ9 -> 3843612.5 | KG5: 600 | KH5: 2100000 | KJ5: =(KH5/KG5) -> 3500 | KK5: 2.9 | KL5: =KJ7*KK5*KG9 -> 3650955 | KN5: 645 | KO5: 2160000 | KQ5: =(KO5/KN5) -> 3348.8372 | KR5: 3.1 | KS5: =KQ7*KR5*KN9 -> 4021010 | KU5: 600 | KV5: 2800000 | KX5: =(KV5/KU5) -> 4666.6667 | KY5: 3 | KZ5: =KX7*KY5*KU9 -> 3834075 | LB5: 600 | LC5: 2600000 | LE5: =(LC5/LB5) -> 4333.3333 | LF5: 3 | LG5: =LE7*LF5*LB9 -> 3719625 | LI5: 600 | LJ5: 2200000 | LL5: =(LJ5/LI5) -> 3666.6667 | LM5: 2.2 | LN5: =LL7*LM5*LI9 -> 2769690 | LP5: 600 | LQ5: 2600000 | LS5: =(LQ5/LP5) -> 4333.3333 | LT5: 3 | LU5: =LS7*LT5*LP9 -> 3776850 | LW5: 600 | LX5: 2600000 | LZ5: =(LX5/LW5) -> 4333.3333 | MA5: 3.5 | MB5: =LZ7*MA5*LW9 -> 4005750 | MD5: 600 | ME5: 2600000 | MG5: =(ME5/MD5) -> 4333.3333 | MH5: 3.5 | MI5: =MG7*MH5*MD9 -> 4005750 | MK5: 600 | ML5: 2600000 | MN5: =(ML5/MK5) -> 4333.3333 | MO5: 3.5 | MP5: =MN7*MO5*MK9 -> 4005750 | MR5: 600 | MS5: 2600000 | MU5: =(MS5/MR5) -> 4333.3333 | MV5: 3.5 | MW5: =MU7*MV5*MR9 -> 4005750 | MY5: 600 | MZ5: 2600000 | NB5: =(MZ5/MY5) -> 4333.3333 | NC5: 3.5 | ND5: =NB7*NC5*MY9 -> 4005750 | NF5: 600 | NG5: 2600000 | NI5: =(NG5/NF5) -> 4333.3333 | NJ5: 3.5 | NK5: =NI7*NJ5*NF9 -> 4005750 | NM5: 600 | NN5: 2600000 | NP5: =(NN5/NM5) -> 4333.3333 | NQ5: 3.5 | NR5: =NP7*NQ5*NM9 -> 2572500
C6: PROD | F6: Eff. | G6: H besoin | I6: H aff. | K6: ▲ | M6: Eff. | N6: H besoin | P6: H aff. | R6: ▲ | T6: Eff. | U6: H besoin | W6: H aff. | Y6: ▲ | AA6: Eff. | AB6: H besoin | AD6: H aff. | AF6: ▲ | AH6: Eff. | AI6: H besoin | AK6: H aff. | AM6: ▲ | AO6: Eff. | AP6: H besoin | AR6: H aff. | AT6: ▲ | AV6: Eff. | AW6: H besoin | AY6: H aff. | BA6: ▲ | BC6: Eff. | BD6: H besoin | BF6: H aff. | BH6: ▲ | BJ6: Eff. | BK6: H besoin | BM6: H aff. | BO6: ▲ | BQ6: Eff. | BR6: H besoin | BT6: H aff. | BV6: ▲ | BX6: Eff. | BY6: H besoin | CA6: H aff. | CC6: ▲ | CE6: Eff. | CF6: H besoin | CH6: H aff. | CJ6: ▲ | CL6: Eff. | CM6: H besoin | CO6: H aff. | CQ6: ▲ | CS6: Eff. | CT6: H besoin | CV6: H aff. | CX6: ▲ | CZ6: Eff. | DA6: H besoin | DC6: H aff. | DE6: ▲ | DG6: Eff. | DH6: H besoin | DJ6: H aff. | DL6: ▲ | DN6: Eff. | DO6: H besoin | DQ6: H aff. | DS6: ▲ | DU6: Eff. | DV6: H besoin | DX6: H aff. | DZ6: ▲ | EB6: Eff. | EC6: H besoin | EE6: H aff. | EG6: ▲ | EI6: Eff. | EJ6: H besoin | EL6: H aff. | EN6: ▲ | EP6: Eff. | EQ6: H besoin | ES6: H aff. | EU6: ▲ | EW6: Eff. | EX6: H besoin | EZ6: H aff. | FB6: ▲ | FD6: Eff. | FE6: H besoin | FG6: H aff. | FI6: ▲ | FK6: Eff. | FL6: H besoin | FN6: H aff. | FP6: ▲ | FR6: Eff. | FS6: H besoin | FU6: H aff. | FW6: ▲ | FY6: Eff. | FZ6: H besoin | GB6: H aff. | GD6: ▲ | GF6: Eff. | GG6: H besoin | GI6: H aff. | GK6: ▲ | GM6: Eff. | GN6: H besoin | GP6: H aff. | GR6: ▲ | GT6: Eff. | GU6: H besoin | GW6: H aff. | GY6: ▲ | HA6: Eff. | HB6: H besoin | HD6: H aff. | HF6: ▲ | HH6: Eff. | HI6: H besoin | HK6: H aff. | HM6: ▲ | HO6: Eff. | HP6: H besoin | HR6: H aff. | HT6: ▲ | HV6: Eff. | HW6: H besoin | HY6: H aff. | IA6: ▲ | IC6: Eff. | ID6: H besoin | IF6: H aff. | IH6: ▲ | IJ6: Eff. | IK6: H besoin | IM6: H aff. | IO6: ▲ | IQ6: Eff. | IR6: H besoin | IT6: H aff. | IV6: ▲ | IX6: Eff. | IY6: H besoin | JA6: H aff. | JC6: ▲ | JE6: Eff. | JF6: H besoin | JH6: H aff. | JJ6: ▲ | JL6: Eff. | JM6: H besoin | JO6: H aff. | JQ6: ▲ | JS6: Eff. | JT6: H besoin | JV6: H aff. | JX6: ▲ | JZ6: Eff. | KA6: H besoin | KC6: H aff. | KE6: ▲ | KG6: Eff. | KH6: H besoin | KJ6: H aff. | KL6: ▲ | KN6: Eff. | KO6: H besoin | KQ6: H aff. | KS6: ▲ | KU6: Eff. | KV6: H besoin | KX6: H aff. | KZ6: ▲ | LB6: Eff. | LC6: H besoin | LE6: H aff. | LG6: ▲ | LI6: Eff. | LJ6: H besoin | LL6: H aff. | LN6: ▲ | LP6: Eff. | LQ6: H besoin | LS6: H aff. | LU6: ▲ | LW6: Eff. | LX6: H besoin | LZ6: H aff. | MB6: ▲ | MD6: Eff. | ME6: H besoin | MG6: H aff. | MI6: ▲ | MK6: Eff. | ML6: H besoin | MN6: H aff. | MP6: ▲ | MR6: Eff. | MS6: H besoin | MU6: H aff. | MW6: ▲ | MY6: Eff. | MZ6: H besoin | NB6: H aff. | ND6: ▲ | NF6: Eff. | NG6: H besoin | NI6: H aff. | NK6: ▲ | NM6: Eff. | NN6: H besoin | NP6: H aff. | NR6: ▲
F7: =F14+F21+F28 -> 107 | G7: =(G5/F5)*(1-0.4) -> 2600 | I7: =I14+I21+I28 -> 3745 | K7: =IF(G7<>0,I7-G7,0) -> 1145 | L7: =L14+L21+L28 -> 12.228571 | M7: =M14+M21+M28 -> 105.6 | N7: =(N5/M5)*(1-0.4) -> 2600 | P7: =P14+P21+P28 -> 3696 | R7: =IF(N7<>0,P7-N7,0) -> 1096 | S7: =S14+S21+S28 -> 12.228571 | T7: =T14+T21+T28 -> 97 | U7: =(U5/T5)*(1-0.4) -> 3000 | W7: =W14+W21+W28 -> 4074 | Y7: =IF(U7<>0,W7-U7,0) -> 1074 | Z7: =Z14+Z21+Z28 -> 13.428571 | AA7: =AA14+AA21+AA28 -> 95 | AB7: =SUM(AB14,AB21,AB28) -> 2084.507 | AD7: =AD14+AD21+AD28 -> 3325 | AF7: =IF(AB7<>0,AD7-AB7,0) -> 1240.493 | AG7: =AG14+AG21+AG28 -> 35.442656 | AH7: =AH14+AH21+AH28 -> 93 | AI7: =SUM(AI14,AI21,AI28) -> 2450.7042 | AK7: =AK14+AK21+AK28 -> 3255 | AM7: =IF(AI7<>0,AK7-AI7,0) -> 804.29577 | AO7: =AO14+AO21+AO28 -> 95 | AP7: =SUM(AP14,AP21,AP28) -> 2707.0423 | AR7: =AR14+AR21+AR28 -> 3705 | AT7: =IF(AP7<>0,AR7-AP7,0) -> 997.95775 | AU7: =AU14+AU21+AU28 -> 28.513078 | AV7: =AV14+AV21+AV28 -> 93.8 | AW7: =SUM(AW14,AW21,AW28) -> 2713.615 | AY7: =AY14+AY21+AY28 -> 3283 | BA7: =IF(AW7<>0,AY7-AW7,0) -> 569.38498 | BB7: =BB14+BB21+BB28 -> 16.268142 | BC7: =BC14+BC21+BC28 -> 93 | BD7: =SUM(BD14,BD21,BD28) -> 2616.7002 | BF7: =BF14+BF21+BF28 -> 3255 | BH7: =IF(BD7<>0,BF7-BD7,0) -> 638.2998 | BI7: =BI14+BI21+BI28 -> 18.237137 | BJ7: =BJ14+BJ21+BJ28 -> 100 | BK7: =SUM(BK14,BK21,BK28) -> 2709.375 | BM7: =BM14+BM21+BM28 -> 3500 | BO7: =IF(BK7<>0,BM7-BK7,0) -> 790.625 | BP7: =BP14+BP21+BP28 -> 22.589286 | BQ7: =BQ14+BQ21+BQ28 -> 100 | BR7: =SUM(BR14,BR21,BR28) -> 2714.8148 | BT7: =BT14+BT21+BT28 -> 3500 | BV7: =IF(BR7<>0,BT7-BR7,0) -> 785.18519 | BW7: =BW14+BW21+BW28 -> 22.433862 | BX7: =BX14+BX21+BX28 -> 93 | BY7: =SUM(BY14,BY21,BY28) -> 2902.9018 | CA7: =CA14+CA21+CA28 -> 3430 | CC7: =IF(BY7<>0,CA7-BY7,0) -> 527.09821 | CD7: =CD14+CD21+CD28 -> 15.059949 | CE7: =CE14+CE21+CE28 -> 92 | CF7: =SUM(CF14,CF21,CF28) -> 2017.1906 | CH7: =CH14+CH21+CH28 -> 3220 | CJ7: =IF(CF7<>0,CH7-CF7,0) -> 1202.8094 | CK7: =CK14+CK21+CK28 -> 34.365982 | CL7: =CL14+CL21+CL28 -> 94 | CM7: =SUM(CM14,CM21,CM28) -> 2581.6377 | CO7: =CO14+CO21+CO28 -> 3290 | CQ7: =IF(CM7<>0,CO7-CM7,0) -> 708.36228 | CR7: =CR14+CR21+CR28 -> 20.238922 | CS7: =CS14+CS21+CS28 -> 95 | CT7: =SUM(CT14,CT21,CT28) -> 2709.375 | CV7: =CV14+CV21+CV28 -> 3325 | CX7: =IF(CT7<>0,CV7-CT7,0) -> 615.625 | CY7: =CY14+CY21+CY28 -> 17.589286 | CZ7: =CZ14+CZ21+CZ28 -> 91.4 | DA7: =SUM(DA14,DA21,DA28) -> 2802.8017 | DC7: =DC14+DC21+DC28 -> 3199 | DE7: =IF(DA7<>0,DC7-DA7,0) -> 396.19828 | DF7: =DF14+DF21+DF28 -> 11.319951 | DG7: =DG14+DG21+DG28 -> 80 | DH7: =SUM(DH14,DH21,DH28) -> 2581.6377 | DJ7: =DJ14+DJ21+DJ28 -> 2800 | DL7: =IF(DH7<>0,DJ7-DH7,0) -> 218.36228 | DM7: =DM14+DM21+DM28 -> 6.2389224 | DN7: =DN14+DN21+DN28 -> 77.6 | DO7: =SUM(DO14,DO21,DO28) -> 2194.3574 | DQ7: =DQ14+DQ21+DQ28 -> 2716 | DS7: =IF(DO7<>0,DQ7-DO7,0) -> 521.64263 | DT7: =DT14+DT21+DT28 -> 14.904075 | DU7: =DU14+DU21+DU28 -> 73.8 | DV7: =SUM(DV14,DV21,DV28) -> 2049.3359 | DX7: =DX14+DX21+DX28 -> 2583 | DZ7: =IF(DV7<>0,DX7-DV7,0) -> 533.66414 | EA7: =EA14+EA21+EA28 -> 15.247547 | EB7: =EB14+EB21+EB28 -> 81.6 | EC7: =SUM(EC14,EC21,EC28) -> 2785.0746 | EE7: =EE14+EE21+EE28 -> 2856 | EG7: =IF(EC7<>0,EE7-EC7,0) -> 70.925373 | EH7: =SUM(EH14+EH21+EH28) -> 2.0264392 | EI7: =EI14+EI21+EI28 -> 87.6 | EJ7: =SUM(EJ14,EJ21,EJ28) -> 2667.6923 | EL7: =EL14+EL21+EL28 -> 3066 | EN7: =IF(EJ7<>0,EL7-EJ7,0) -> 398.30769 | EO7: =EO14+EO21+EO28 -> 11.38022 | EP7: =EP14+EP21+EP28 -> 91 | EQ7: =SUM(EQ14,EQ21,EQ28) -> 3028.9256 | ES7: =ES14+ES21+ES28 -> 3185 | EU7: =IF(EQ7<>0,ES7-EQ7,0) -> 156.07438 | EV7: =EV14+EV21+EV28 -> 4.459268 | EW7: =EW14+EW21+EW28 -> 85 | EX7: =SUM(EX14,EX21,EX28) -> 2627.2727 | EZ7: =EZ14+EZ21+EZ28 -> 2975 | FB7: =IF(EX7<>0,EZ7-EX7,0) -> 347.72727 | FC7: =FC14+FC21+FC28 -> 9.9350649 | FD7: =FD14+FD21+FD28 -> 90 | FE7: =SUM(FE14,FE21,FE28) -> 2727.2727 | FG7: =FG14+FG21+FG28 -> 3150 | FI7: =IF(FE7<>0,FG7-FE7,0) -> 422.72727 | FJ7: =FJ14+FJ21+FJ28 -> 12.077922 | FK7: =FK14+FK21+FK28 -> 75 | FL7: =SUM(FL14,FL21,FL28) -> 2812.5 | FN7: =FN14+FN21+FN28 -> 2925 | FP7: =IF(FL7<>0,FN7-FL7,0) -> 112.5 | FQ7: =FQ14+FQ21+FQ28 -> 3.2142857 | FR7: =FR14+FR21+FR28 -> 87 | FS7: =SUM(FS14,FS21,FS28) -> 3030.303 | FU7: =FU14+FU21+FU28 -> 3045 | FW7: =IF(FS7<>0,FU7-FS7,0) -> 14.69697 | FX7: =FX14+FX21+FX28 -> 0.41991342 | FY7: =FY14+FY21+FY28 -> 87.4 | FZ7: =SUM(FZ14,FZ21,FZ28) -> 3125 | GB7: =GB14+GB21+GB28 -> 3059 | GD7: =IF(FZ7<>0,GB7-FZ7,0) -> -66 | GE7: =GE14+GE21+GE28 -> -1.8857143 | GF7: =GF14+GF21+GF28 -> 84 | GG7: =SUM(GG14,GG21,GG28) -> 3125 | GI7: =GI14+GI21+GI28 -> 2940 | GK7: =IF(GG7<>0,GI7-GG7,0) -> -185 | GL7: =GL14+GL21+GL28 -> -5.2857143 | GM7: =GM14+GM21+GM28 -> 82 | GN7: =SUM(GN14,GN21,GN28) -> 3125 | GP7: =GP14+GP21+GP28 -> 2870 | GR7: =IF(GN7<>0,GP7-GN7,0) -> -255 | GS7: =GS14+GS21+GS28 -> -7.2857143 | GT7: =GT14+GT21+GT28 -> 65.2 | GU7: =SUM(GU14,GU21,GU28) -> 2709.375 | GW7: =GW14+GW21+GW28 -> 2282 | GY7: =IF(GU7<>0,GW7-GU7,0) -> -427.375 | GZ7: =GZ14+GZ21+GZ28 -> -12.210714 | HA7: =HA14+HA21+HA28 -> 75 | HB7: =SUM(HB14,HB21,HB28) -> 2718.75 | HD7: =HD14+HD21+HD28 -> 2625 | HF7: =IF(HB7<>0,HD7-HB7,0) -> -93.75 | HH7: =HH14+HH21+HH28 -> 68 | HI7: =SUM(HI14,HI21,HI28) -> 3003.125 | HK7: =HK14+HK21+HK28 -> 2652 | HM7: =IF(HI7<>0,HK7-HI7,0) -> -351.125 | HN7: =HN14+HN21+HN28 -> -10.032143 | HO7: =HO14+HO21+HO28 -> 70 | HP7: =SUM(HP14,HP21,HP28) -> 3125 | HR7: =HR14+HR21+HR28 -> 2450 | HT7: =IF(HP7<>0,HR7-HP7,0) -> -675 | HU7: =HU14+HU21+HU28 -> -19.285714 | HV7: =HV14+HV21+HV28 -> 73 | HW7: =SUM(HW14,HW21,HW28) -> 3125 | HY7: =HY14+HY21+HY28 -> 2555 | IA7: =IF(HW7<>0,HY7-HW7,0) -> -570 | IB7: =IB14+IB21+IB28 -> -16.285714 | IC7: =IC14+IC21+IC28 -> 81 | ID7: =SUM(ID14,ID21,ID28) -> 3125 | IF7: =IF14+IF21+IF28 -> 2835 | IH7: =IF(ID7<>0,IF7-ID7,0) -> -290 | II7: =II14+II21+II28 -> -8.2857143 | IJ7: =IJ14+IJ21+IJ28 -> 86 | IK7: =SUM(IK14,IK21,IK28) -> 2443.3333 | IM7: =IM14+IM21+IM28 -> 3010 | IO7: =IF(IK7<>0,IM7-IK7,0) -> 566.66667 | IP7: =IP14+IP21+IP28 -> 16.190476 | IQ7: =IQ14+IQ21+IQ28 -> 91.6 | IR7: =SUM(IR14,IR21,IR28) -> 2709.375 | IT7: =IT14+IT21+IT28 -> 3066 | IV7: =IF(IR7<>0,IT7-IR7,0) -> 356.625 | IW7: =IW14+IW21+IW28 -> 10.189286 | IX7: =IX14+IX21+IX28 -> 90 | IY7: =SUM(IY14,IY21,IY28) -> 2017.1906 | JA7: =JA14+JA21+JA28 -> 3150 | JC7: =IF(IY7<>0,JA7-IY7,0) -> 1132.8094 | JD7: =JD14+JD21+JD28 -> 32.365982 | JE7: =JE14+JE21+JE28 -> 103 | JF7: =SUM(JF14,JF21,JF28) -> 2581.6377 | JH7: =JH14+JH21+JH28 -> 3605 | JJ7: =IF(JF7<>0,JH7-JF7,0) -> 1023.3623 | JK7: =JK14+JK21+JK28 -> 29.238922 | JL7: =JL14+JL21+JL28 -> 107 | JM7: =SUM(JM14,JM21,JM28) -> 2709.375 | JO7: =JO14+JO21+JO28 -> 3745 | JQ7: =IF(JM7<>0,JO7-JM7,0) -> 1035.625 | JR7: =JR14+JR21+JR28 -> 29.589286 | JS7: =JS14+JS21+JS28 -> 109 | JT7: =SUM(JT14,JT21,JT28) -> 2802.8017 | JV7: =JV14+JV21+JV28 -> 3815 | JX7: =IF(JT7<>0,JV7-JT7,0) -> 1012.1983 | JY7: =JY14+JY21+JY28 -> 28.919951 | JZ7: =JZ14+JZ21+JZ28 -> 109 | KA7: =SUM(KA14,KA21,KA28) -> 2581.6377 | KC7: =KC14+KC21+KC28 -> 3815 | KE7: =IF(KA7<>0,KC7-KA7,0) -> 1233.3623 | KF7: =KF14+KF21+KF28 -> 35.238922 | KG7: =KG14+KG21+KG28 -> 109 | KH7: =SUM(KH14,KH21,KH28) -> 2194.3574 | KJ7: =KJ14+KJ21+KJ28 -> 3815 | KL7: =IF(KH7<>0,KJ7-KH7,0) -> 1620.6426 | KM7: =KM14+KM21+KM28 -> 46.304075 | KN7: =KN14+KN21+KN28 -> 109 | KO7: =SUM(KO14,KO21,KO28) -> 2049.3359 | KQ7: =KQ14+KQ21+KQ28 -> 3815 | KS7: =IF(KO7<>0,KQ7-KO7,0) -> 1765.6641 | KT7: =KT14+KT21+KT28 -> 50.447547 | KU7: =KU14+KU21+KU28 -> 109 | KV7: =SUM(KV14,KV21,KV28) -> 2785.0746 | KX7: =KX14+KX21+KX28 -> 3815 | KZ7: =IF(KV7<>0,KX7-KV7,0) -> 1029.9254 | LA7: =SUM(LA14+LA21+LA28) -> 29.426439 | LB7: =LB14+LB21+LB28 -> 109 | LC7: =SUM(LC14,LC21,LC28) -> 2667.6923 | LE7: =LE14+LE21+LE28 -> 3815 | LG7: =IF(LC7<>0,LE7-LC7,0) -> 1147.3077 | LH7: =LH14+LH21+LH28 -> 32.78022 | LI7: =LI14+LI21+LI28 -> 109 | LJ7: =SUM(LJ14,LJ21,LJ28) -> 3028.9256 | LL7: =LL14+LL21+LL28 -> 3815 | LN7: =IF(LJ7<>0,LL7-LJ7,0) -> 786.07438 | LO7: =LO14+LO21+LO28 -> 22.459268 | LP7: =LP14+LP21+LP28 -> 109 | LQ7: =SUM(LQ14,LQ21,LQ28) -> 2627.2727 | LS7: =LS14+LS21+LS28 -> 3815 | LU7: =IF(LQ7<>0,LS7-LQ7,0) -> 1187.7273 | LV7: =LV14+LV21+LV28 -> 33.935065 | LW7: =LW14+LW21+LW28 -> 109 | LX7: =SUM(LX14,LX21,LX28) -> 2477.1429 | LZ7: =LZ14+LZ21+LZ28 -> 3815 | MB7: =IF(LX7<>0,LZ7-LX7,0) -> 1337.8571 | MC7: =MC14+MC21+MC28 -> 38.22449 | MD7: =MD14+MD21+MD28 -> 109 | ME7: =SUM(ME14,ME21,ME28) -> 2477.1429 | MG7: =MG14+MG21+MG28 -> 3815 | MI7: =IF(ME7<>0,MG7-ME7,0) -> 1337.8571 | MJ7: =MJ14+MJ21+MJ28 -> 38.22449 | MK7: =MK14+MK21+MK28 -> 109 | ML7: =SUM(ML14,ML21,ML28) -> 2477.1429 | MN7: =MN14+MN21+MN28 -> 3815 | MP7: =IF(ML7<>0,MN7-ML7,0) -> 1337.8571 | MQ7: =MQ14+MQ21+MQ28 -> 38.22449 | MR7: =MR14+MR21+MR28 -> 109 | MS7: =SUM(MS14,MS21,MS28) -> 2477.1429 | MU7: =MU14+MU21+MU28 -> 3815 | MW7: =IF(MS7<>0,MU7-MS7,0) -> 1337.8571 | MX7: =MX14+MX21+MX28 -> 38.22449 | MY7: =MY14+MY21+MY28 -> 109 | MZ7: =SUM(MZ14,MZ21,MZ28) -> 2477.1429 | NB7: =NB14+NB21+NB28 -> 3815 | ND7: =IF(MZ7<>0,NB7-MZ7,0) -> 1337.8571 | NE7: =NE14+NE21+NE28 -> 38.22449 | NF7: =NF14+NF21+NF28 -> 109 | NG7: =SUM(NG14,NG21,NG28) -> 2477.1429 | NI7: =NI14+NI21+NI28 -> 3815 | NK7: =IF(NG7<>0,NI7-NG7,0) -> 1337.8571 | NL7: =NL14+NL21+NL28 -> 38.22449 | NM7: =NM14+NM21+NM28 -> 70 | NN7: =SUM(NN14,NN21,NN28) -> 2477.1429 | NP7: =NP14+NP21+NP28 -> 2450 | NR7: =IF(NN7<>0,NP7-NN7,0) -> -27.142857 | NS7: =NS14+NS21+NS28 -> -0.7755102
F8: Cad.moy | G8: Pcs fdr | I8: Pcs théo | K8: ▲ | M8: Cad.moy | N8: Pcs fdr | P8: Pcs théo | R8: ▲ | T8: Cad.moy | U8: Pcs fdr | W8: Pcs théo | Y8: ▲ | AA8: Cad.moy | AB8: Pcs fdr | AD8: Pcs théo | AF8: ▲ | AH8: Cad.moy | AI8: Pcs fdr | AK8: Pcs théo | AM8: ▲ | AO8: Cad.moy | AP8: Pcs fdr | AR8: Pcs théo | AT8: ▲ | AV8: Cad.moy | AW8: Pcs fdr | AY8: Pcs théo | BA8: ▲ | BC8: Cad.moy | BD8: Pcs fdr | BF8: Pcs théo | BH8: ▲ | BJ8: Cad.moy | BK8: Pcs fdr | BM8: Pcs théo | BO8: ▲ | BQ8: Cad.moy | BR8: Pcs fdr | BT8: Pcs théo | BV8: ▲ | BX8: Cad.moy | BY8: Pcs fdr | CA8: Pcs théo | CC8: ▲ | CE8: Cad.moy | CF8: Pcs fdr | CH8: Pcs théo | CJ8: ▲ | CL8: Cad.moy | CM8: Pcs fdr | CO8: Pcs théo | CQ8: ▲ | CS8: Cad.moy | CT8: Pcs fdr | CV8: Pcs théo | CX8: ▲ | CZ8: Cad.moy | DA8: Pcs fdr | DC8: Pcs théo | DE8: ▲ | DG8: Cad.moy | DH8: Pcs fdr | DJ8: Pcs théo | DL8: ▲ | DN8: Cad.moy | DO8: Pcs fdr | DQ8: Pcs théo | DS8: ▲ | DU8: Cad.moy | DV8: Pcs fdr | DX8: Pcs théo | DZ8: ▲ | EB8: Cad.moy | EC8: Pcs fdr | EE8: Pcs théo | EG8: ▲ | EI8: Cad.moy | EJ8: Pcs fdr | EL8: Pcs théo | EN8: ▲ | EP8: Cad.moy | EQ8: Pcs fdr | ES8: Pcs théo | EU8: ▲ | EW8: Cad.moy | EX8: Pcs fdr | EZ8: Pcs théo | FB8: ▲ | FD8: Cad.moy | FE8: Pcs fdr | FG8: Pcs théo | FI8: ▲ | FK8: Cad.moy | FL8: Pcs fdr | FN8: Pcs théo | FP8: ▲ | FR8: Cad.moy | FS8: Pcs fdr | FU8: Pcs théo | FW8: ▲ | FY8: Cad.moy | FZ8: Pcs fdr | GB8: Pcs théo | GD8: ▲ | GF8: Cad.moy | GG8: Pcs fdr | GI8: Pcs théo | GK8: ▲ | GM8: Cad.moy | GN8: Pcs fdr | GP8: Pcs théo | GR8: ▲ | GT8: Cad.moy | GU8: Pcs fdr | GW8: Pcs théo | GY8: ▲ | HA8: Cad.moy | HB8: Pcs fdr | HD8: Pcs théo | HF8: ▲ | HH8: Cad.moy | HI8: Pcs fdr | HK8: Pcs théo | HM8: ▲ | HO8: Cad.moy | HP8: Pcs fdr | HR8: Pcs théo | HT8: ▲ | HV8: Cad.moy | HW8: Pcs fdr | HY8: Pcs théo | IA8: ▲ | IC8: Cad.moy | ID8: Pcs fdr | IF8: Pcs théo | IH8: ▲ | IJ8: Cad.moy | IK8: Pcs fdr | IM8: Pcs théo | IO8: ▲ | IQ8: Cad.moy | IR8: Pcs fdr | IT8: Pcs théo | IV8: ▲ | IX8: Cad.moy | IY8: Pcs fdr | JA8: Pcs théo | JC8: ▲ | JE8: Cad.moy | JF8: Pcs fdr | JH8: Pcs théo | JJ8: ▲ | JL8: Cad.moy | JM8: Pcs fdr | JO8: Pcs théo | JQ8: ▲ | JS8: Cad.moy | JT8: Pcs fdr | JV8: Pcs théo | JX8: ▲ | JZ8: Cad.moy | KA8: Pcs fdr | KC8: Pcs théo | KE8: ▲ | KG8: Cad.moy | KH8: Pcs fdr | KJ8: Pcs théo | KL8: ▲ | KN8: Cad.moy | KO8: Pcs fdr | KQ8: Pcs théo | KS8: ▲ | KU8: Cad.moy | KV8: Pcs fdr | KX8: Pcs théo | KZ8: ▲ | LB8: Cad.moy | LC8: Pcs fdr | LE8: Pcs théo | LG8: ▲ | LI8: Cad.moy | LJ8: Pcs fdr | LL8: Pcs théo | LN8: ▲ | LP8: Cad.moy | LQ8: Pcs fdr | LS8: Pcs théo | LU8: ▲ | LW8: Cad.moy | LX8: Pcs fdr | LZ8: Pcs théo | MB8: ▲ | MD8: Cad.moy | ME8: Pcs fdr | MG8: Pcs théo | MI8: ▲ | MK8: Cad.moy | ML8: Pcs fdr | MN8: Pcs théo | MP8: ▲ | MR8: Cad.moy | MS8: Pcs fdr | MU8: Pcs théo | MW8: ▲ | MY8: Cad.moy | MZ8: Pcs fdr | NB8: Pcs théo | ND8: ▲ | NF8: Cad.moy | NG8: Pcs fdr | NI8: Pcs théo | NK8: ▲ | NM8: Cad.moy | NN8: Pcs fdr | NP8: Pcs théo | NR8: ▲
F9: =ROUND(AVERAGE(F16,F23,F30),0) -> 330 | G9: =G16+G23+G30 -> 0 | I9: =I16+I23+I30 -> 1235850 | K9: =IF(G9<>0,I9-G9,0) -> 0 | M9: =ROUND(AVERAGE(M16,M23,M30),0) -> 317 | N9: =N16+N23+N30 -> 0 | P9: =P16+P23+P30 -> 1164100 | R9: =IF(N9<>0,P9-N9,0) -> 0 | T9: =ROUND(AVERAGE(T16,T23,T30),0) -> 355 | U9: =U16+U23+U30 -> 0 | W9: =W16+W23+W30 -> 1446270 | Y9: =IF(U9<>0,W9-U9,0) -> 0 | AA9: =ROUND(((AB16*AA16+AB23*AA23+AB30*AA30)/AB9),0) -> 355 | AB9: =AB16+AB23+AB30 -> 740000 | AD9: =AD16+AD23+AD30 -> 1180375 | AF9: =IF(AB9<>0,AD9-AB9,0) -> 440375 | AH9: =ROUND(((AK16*AH16+AK23*AH23+AK30*AH30)/AK9),0) -> 355 | AI9: =AI16+AI23+AI30 -> 870000 | AK9: =AK16+AK23+AK30 -> 1155525 | AM9: =IF(AI9<>0,AK9-AI9,0) -> 285525 | AO9: =IFERROR(ROUND(((AP16*AO16+AP23*AO23+AP30*AO30)/AP9),0),0) -> 355 | AP9: =AP16+AP23+AP30 -> 961000 | AR9: =AR16+AR23+AR30 -> 1315275 | AT9: =IF(AP9<>0,AR9-AP9,0) -> 354275 | AV9: =IFERROR(ROUND(((AW16*AV16+AW23*AV23+AW30*AV30)/AW9),0),0) -> 355 | AW9: =AW16+AW23+AW30 -> 963333.33 | AY9: =AY16+AY23+AY30 -> 1165465 | BA9: =IF(AW9<>0,AY9-AW9,0) -> 202131.67 | BC9: =IFERROR(ROUND(((BD16*BC16+BD23*BC23+BD30*BC30)/BD9),0),0) -> 355 | BD9: =BD16+BD23+BD30 -> 928928.57 | BF9: =BF16+BF23+BF30 -> 1155525 | BH9: =IF(BD9<>0,BF9-BD9,0) -> 226596.43 | BJ9: =IFERROR(ROUND(((BK16*BJ16+BK23*BJ23+BK30*BJ30)/BK9),0),0) -> 300 | BK9: =BK16+BK23+BK30 -> 812812.5 | BM9: =BM16+BM23+BM30 -> 1050000 | BO9: =IF(BK9<>0,BM9-BK9,0) -> 237187.5 | BQ9: =IFERROR(ROUND(((BR16*BQ16+BR23*BQ23+BR30*BQ30)/BR9),0),0) -> 300 | BR9: =BR16+BR23+BR30 -> 814444.44 | BT9: =BT16+BT23+BT30 -> 1050000 | BV9: =IF(BR9<>0,BT9-BR9,0) -> 235555.56 | BX9: =IFERROR(ROUND(((BY16*BX16+BY23*BX23+BY30*BX30)/BY9),0),0) -> 320 | BY9: =BY16+BY23+BY30 -> 928928.57 | CA9: =CA16+CA23+CA30 -> 1097600 | CC9: =IF(BY9<>0,CA9-BY9,0) -> 168671.43 | CE9: =IFERROR(ROUND(((CF16*CE16+CF23*CE23+CF30*CE30)/CF9),0),0) -> 320 | CF9: =CF16+CF23+CF30 -> 645501 | CH9: =CH16+CH23+CH30 -> 1030400 | CJ9: =IF(CF9<>0,CH9-CF9,0) -> 384899 | CL9: =IFERROR(ROUND(((CM16*CL16+CM23*CL23+CM30*CL30)/CM9),0),0) -> 325 | CM9: =CM16+CM23+CM30 -> 839032.26 | CO9: =CO16+CO23+CO30 -> 1069250 | CQ9: =IF(CM9<>0,CO9-CM9,0) -> 230217.74 | CS9: =IFERROR(ROUND(((CT16*CS16+CT23*CS23+CT30*CS30)/CT9),0),0) -> 320 | CT9: =CT16+CT23+CT30 -> 867000 | CV9: =CV16+CV23+CV30 -> 1064000 | CX9: =IF(CT9<>0,CV9-CT9,0) -> 197000 | CZ9: =IFERROR(ROUND(((DA16*CZ16+DA23*CZ23+DA30*CZ30)/DA9),0),0) -> 320 | DA9: =DA16+DA23+DA30 -> 896896.55 | DC9: =DC16+DC23+DC30 -> 1023680 | DE9: =IF(DA9<>0,DC9-DA9,0) -> 126783.45 | DG9: =IFERROR(ROUND(((DH16*DG16+DH23*DG23+DH30*DG30)/DH9),0),0) -> 325 | DH9: =DH16+DH23+DH30 -> 839032.26 | DJ9: =DJ16+DJ23+DJ30 -> 910000 | DL9: =IF(DH9<>0,DJ9-DH9,0) -> 70967.742 | DN9: =IFERROR(ROUND(((DO16*DN16+DO23*DN23+DO30*DN30)/DO9),0),0) -> 330 | DO9: =DO16+DO23+DO30 -> 724137.93 | DQ9: =DQ16+DQ23+DQ30 -> 896280 | DS9: =IF(DO9<>0,DQ9-DO9,0) -> 172142.07 | DU9: =IFERROR(ROUND(((DV16*DU16+DV23*DU23+DV30*DU30)/DV9),0),0) -> 340 | DV9: =DV16+DV23+DV30 -> 696774.19 | DX9: =DX16+DX23+DX30 -> 878220 | DZ9: =IF(DV9<>0,DX9-DV9,0) -> 181445.81 | EB9: =IFERROR(ROUND(((EC16*EB16+EC23*EB23+EC30*EB30)/EC9),0),0) -> 335 | EC9: =EC16+EC23+EC30 -> 933000 | EE9: =EE16+EE23+EE30 -> 956760 | EG9: =IF(EC9<>0,EE9-EC9,0) -> 23760 | EI9: =IFERROR(ROUND(((EJ16*EI16+EJ23*EI23+EJ30*EI30)/EJ9),0),0) -> 325 | EJ9: =EJ16+EJ23+EJ30 -> 867000 | EL9: =EL16+EL23+EL30 -> 996450 | EN9: =IF(EJ9<>0,EL9-EJ9,0) -> 129450 | EP9: =IFERROR(ROUND(((EQ16*EP16+EQ23*EP23+EQ30*EP30)/EQ9),0),0) -> 330 | EQ9: =EQ16+EQ23+EQ30 -> 999545.45 | ES9: =ES16+ES23+ES30 -> 1051050 | EU9: =IF(EQ9<>0,ES9-EQ9,0) -> 51504.545 | EW9: =IFERROR(ROUND(((EX16*EW16+EX23*EW23+EX30*EW30)/EX9),0),0) -> 330 | EX9: =EX16+EX23+EX30 -> 867000 | EZ9: =EZ16+EZ23+EZ30 -> 981750 | FB9: =IF(EX9<>0,EZ9-EX9,0) -> 114750 | FD9: =IFERROR(ROUND(((FE16*FD16+FE23*FD23+FE30*FD30)/FE9),0),0) -> 330 | FE9: =FE16+FE23+FE30 -> 900000 | FG9: =FG16+FG23+FG30 -> 1039500 | FI9: =IF(FE9<>0,FG9-FE9,0) -> 139500 | FK9: =IFERROR(ROUND(((FL16*FK16+FL23*FK23+FL30*FK30)/FL9),0),0) -> 320 | FL9: =FL16+FL23+FL30 -> 900000 | FN9: =FN16+FN23+FN30 -> 936000 | FP9: =IF(FL9<>0,FN9-FL9,0) -> 36000 | FR9: =IFERROR(ROUND(((FS16*FR16+FS23*FR23+FS30*FR30)/FS9),0),0) -> 330 | FS9: =FS16+FS23+FS30 -> 1000000 | FU9: =FU16+FU23+FU30 -> 1004850 | FW9: =IF(FS9<>0,FU9-FS9,0) -> 4850 | FY9: =IFERROR(ROUND(((FZ16*FY16+FZ23*FY23+FZ30*FY30)/FZ9),0),0) -> 320 | FZ9: =FZ16+FZ23+FZ30 -> 1000000 | GB9: =GB16+GB23+GB30 -> 978880 | GD9: =IF(FZ9<>0,GB9-FZ9,0) -> -21120 | GF9: =IFERROR(ROUND(((GG16*GF16+GG23*GF23+GG30*GF30)/GG9),0),0) -> 320 | GG9: =GG16+GG23+GG30 -> 1000000 | GI9: =GI16+GI23+GI30 -> 940800 | GK9: =IF(GG9<>0,GI9-GG9,0) -> -59200 | GM9: =IFERROR(ROUND(((GN16*GM16+GN23*GM23+GN30*GM30)/GN9),0),0) -> 320 | GN9: =GN16+GN23+GN30 -> 1000000 | GP9: =GP16+GP23+GP30 -> 918400 | GR9: =IF(GN9<>0,GP9-GN9,0) -> -81600 | GT9: =IFERROR(ROUND(((GU16*GT16+GU23*GT23+GU30*GT30)/GU9),0),0) -> 320 | GU9: =GU16+GU23+GU30 -> 867000 | GW9: =GW16+GW23+GW30 -> 730240 | GY9: =IF(GU9<>0,GW9-GU9,0) -> -136760 | HA9: =ROUND(((HD16*HA16+HD23*HA23+HD30*HA30)/HD9),0) -> 320 | HB9: =HB16+HB23+HB30 -> 870000 | HD9: =HD16+HD23+HD30 -> 840000 | HF9: =IF(HB9<>0,HD9-HB9,0) -> -30000 | HH9: =IFERROR(ROUND(((HI16*HH16+HI23*HH23+HI30*HH30)/HI9),0),0) -> 320 | HI9: =HI16+HI23+HI30 -> 961000 | HK9: =HK16+HK23+HK30 -> 848640 | HM9: =IF(HI9<>0,HK9-HI9,0) -> -112360 | HO9: =IFERROR(ROUND(((HP16*HO16+HP23*HO23+HP30*HO30)/HP9),0),0) -> 320 | HP9: =HP16+HP23+HP30 -> 1000000 | HR9: =HR16+HR23+HR30 -> 784000 | HT9: =IF(HP9<>0,HR9-HP9,0) -> -216000 | HV9: =IFERROR(ROUND(((HW16*HV16+HW23*HV23+HW30*HV30)/HW9),0),0) -> 320 | HW9: =HW16+HW23+HW30 -> 1000000 | HY9: =HY16+HY23+HY30 -> 817600 | IA9: =IF(HW9<>0,HY9-HW9,0) -> -182400 | IC9: =IFERROR(ROUND(((ID16*IC16+ID23*IC23+ID30*IC30)/ID9),0),0) -> 320 | ID9: =ID16+ID23+ID30 -> 1000000 | IF9: =IF16+IF23+IF30 -> 907200 | IH9: =IF(ID9<>0,IF9-ID9,0) -> -92800 | IJ9: =IFERROR(ROUND(((IK16*IJ16+IK23*IJ23+IK30*IJ30)/IK9),0),0) -> 300 | IK9: =IK16+IK23+IK30 -> 733000 | IM9: =IM16+IM23+IM30 -> 903000 | IO9: =IF(IK9<>0,IM9-IK9,0) -> 170000 | IQ9: =IFERROR(ROUND(((IR16*IQ16+IR23*IQ23+IR30*IQ30)/IR9),0),0) -> 320 | IR9: =IR16+IR23+IR30 -> 867000 | IT9: =IT16+IT23+IT30 -> 981120 | IV9: =IF(IR9<>0,IT9-IR9,0) -> 114120 | IX9: =IFERROR(ROUND(((IY16*IX16+IY23*IX23+IY30*IX30)/IY9),0),0) -> 320 | IY9: =IY16+IY23+IY30 -> 645501 | JA9: =JA16+JA23+JA30 -> 1008000 | JC9: =IF(IY9<>0,JA9-IY9,0) -> 362499 | JE9: =IFERROR(ROUND(((JF16*JE16+JF23*JE23+JF30*JE30)/JF9),0),0) -> 325 | JF9: =JF16+JF23+JF30 -> 839032.26 | JH9: =JH16+JH23+JH30 -> 1171625 | JJ9: =IF(JF9<>0,JH9-JF9,0) -> 332592.74 | JL9: =IFERROR(ROUND(((JM16*JL16+JM23*JL23+JM30*JL30)/JM9),0),0) -> 320 | JM9: =JM16+JM23+JM30 -> 867000 | JO9: =JO16+JO23+JO30 -> 1198400 | JQ9: =IF(JM9<>0,JO9-JM9,0) -> 331400 | JS9: =IFERROR(ROUND(((JT16*JS16+JT23*JS23+JT30*JS30)/JT9),0),0) -> 320 | JT9: =JT16+JT23+JT30 -> 896896.55 | JV9: =JV16+JV23+JV30 -> 1220800 | JX9: =IF(JT9<>0,JV9-JT9,0) -> 323903.45 | JZ9: =IFERROR(ROUND(((KA16*JZ16+KA23*JZ23+KA30*JZ30)/KA9),0),0) -> 325 | KA9: =KA16+KA23+KA30 -> 839032.26 | KC9: =KC16+KC23+KC30 -> 1239875 | KE9: =IF(KA9<>0,KC9-KA9,0) -> 400842.74 | KG9: =IFERROR(ROUND(((KH16*KG16+KH23*KG23+KH30*KG30)/KH9),0),0) -> 330 | KH9: =KH16+KH23+KH30 -> 724137.93 | KJ9: =KJ16+KJ23+KJ30 -> 1258950 | KL9: =IF(KH9<>0,KJ9-KH9,0) -> 534812.07 | KN9: =IFERROR(ROUND(((KO16*KN16+KO23*KN23+KO30*KN30)/KO9),0),0) -> 340 | KO9: =KO16+KO23+KO30 -> 696774.19 | KQ9: =KQ16+KQ23+KQ30 -> 1297100 | KS9: =IF(KO9<>0,KQ9-KO9,0) -> 600325.81 | KU9: =IFERROR(ROUND(((KV16*KU16+KV23*KU23+KV30*KU30)/KV9),0),0) -> 335 | KV9: =KV16+KV23+KV30 -> 933000 | KX9: =KX16+KX23+KX30 -> 1278025 | KZ9: =IF(KV9<>0,KX9-KV9,0) -> 345025 | LB9: =IFERROR(ROUND(((LC16*LB16+LC23*LB23+LC30*LB30)/LC9),0),0) -> 325 | LC9: =LC16+LC23+LC30 -> 867000 | LE9: =LE16+LE23+LE30 -> 1239875 | LG9: =IF(LC9<>0,LE9-LC9,0) -> 372875 | LI9: =IFERROR(ROUND(((LJ16*LI16+LJ23*LI23+LJ30*LI30)/LJ9),0),0) -> 330 | LJ9: =LJ16+LJ23+LJ30 -> 999545.45 | LL9: =LL16+LL23+LL30 -> 1258950 | LN9: =IF(LJ9<>0,LL9-LJ9,0) -> 259404.55 | LP9: =IFERROR(ROUND(((LQ16*LP16+LQ23*LP23+LQ30*LP30)/LQ9),0),0) -> 330 | LQ9: =LQ16+LQ23+LQ30 -> 867000 | LS9: =LS16+LS23+LS30 -> 1258950 | LU9: =IF(LQ9<>0,LS9-LQ9,0) -> 391950 | LW9: =IFERROR(ROUND(((LX16*LW16+LX23*LW23+LX30*LW30)/LX9),0),0) -> 300 | LX9: =LX16+LX23+LX30 -> 743142.86 | LZ9: =LZ16+LZ23+LZ30 -> 1144500 | MB9: =IF(LX9<>0,LZ9-LX9,0) -> 401357.14 | MD9: =IFERROR(ROUND(((ME16*MD16+ME23*MD23+ME30*MD30)/ME9),0),0) -> 300 | ME9: =ME16+ME23+ME30 -> 743142.86 | MG9: =MG16+MG23+MG30 -> 1144500 | MI9: =IF(ME9<>0,MG9-ME9,0) -> 401357.14 | MK9: =IFERROR(ROUND(((ML16*MK16+ML23*MK23+ML30*MK30)/ML9),0),0) -> 300 | ML9: =ML16+ML23+ML30 -> 743142.86 | MN9: =MN16+MN23+MN30 -> 1144500 | MP9: =IF(ML9<>0,MN9-ML9,0) -> 401357.14 | MR9: =IFERROR(ROUND(((MS16*MR16+MS23*MR23+MS30*MR30)/MS9),0),0) -> 300 | MS9: =MS16+MS23+MS30 -> 743142.86 | MU9: =MU16+MU23+MU30 -> 1144500 | MW9: =IF(MS9<>0,MU9-MS9,0) -> 401357.14 | MY9: =IFERROR(ROUND(((MZ16*MY16+MZ23*MY23+MZ30*MY30)/MZ9),0),0) -> 300 | MZ9: =MZ16+MZ23+MZ30 -> 743142.86 | NB9: =NB16+NB23+NB30 -> 1144500 | ND9: =IF(MZ9<>0,NB9-MZ9,0) -> 401357.14 | NF9: =IFERROR(ROUND(((NG16*NF16+NG23*NF23+NG30*NF30)/NG9),0),0) -> 300 | NG9: =NG16+NG23+NG30 -> 743142.86 | NI9: =NI16+NI23+NI30 -> 1144500 | NK9: =IF(NG9<>0,NI9-NG9,0) -> 401357.14 | NM9: =IFERROR(ROUND(((NN16*NM16+NN23*NM23+NN30*NM30)/NN9),0),0) -> 300 | NN9: =NN16+NN23+NN30 -> 743142.86 | NP9: =NP16+NP23+NP30 -> 735000 | NR9: =IF(NN9<>0,NP9-NN9,0) -> -8142.8571
F11: Prod. | G11: Valeur obj. | M11: Prod. | N11: Valeur obj. | T11: Prod. | U11: Valeur obj. | AA11: Prod. | AB11: Valeur obj. | AH11: Prod. | AI11: Valeur obj. | AO11: Prod. | AP11: Valeur obj. | AV11: Prod. | AW11: Valeur obj. | BC11: Prod. | BD11: Valeur obj. | BJ11: Prod. | BK11: Valeur obj. | BQ11: Prod. | BR11: Valeur obj. | BX11: Prod. | BY11: Valeur obj. | CE11: Prod. | CF11: Valeur obj. | CL11: Prod. | CM11: Valeur obj. | CS11: Prod. | CT11: Valeur obj. | CZ11: Prod. | DA11: Valeur obj. | DG11: Prod. | DH11: Valeur obj. | DN11: Prod. | DO11: Valeur obj. | DU11: Prod. | DV11: Valeur obj. | EB11: Prod. | EC11: Valeur obj. | EI11: Prod. | EJ11: Valeur obj. | EP11: Prod. | EQ11: Valeur obj. | EW11: Prod. | EX11: Valeur obj. | FD11: Prod. | FE11: Valeur obj. | FK11: Prod. | FL11: Valeur obj. | FR11: Prod. | FS11: Valeur obj. | FY11: Prod. | FZ11: Valeur obj. | GF11: Prod. | GG11: Valeur obj. | GM11: Prod. | GN11: Valeur obj. | GT11: Prod. | GU11: Valeur obj. | HA11: Prod. | HB11: Valeur obj. | HH11: Prod. | HI11: Valeur obj. | HO11: Prod. | HP11: Valeur obj. | HV11: Prod. | HW11: Valeur obj. | IC11: Prod. | ID11: Valeur obj. | IJ11: Prod. | IK11: Valeur obj. | IQ11: Prod. | IR11: Valeur obj. | IX11: Prod. | IY11: Valeur obj. | JE11: Prod. | JF11: Valeur obj. | JL11: Prod. | JM11: Valeur obj. | JS11: Prod. | JT11: Valeur obj. | JZ11: Prod. | KA11: Valeur obj. | KG11: Prod. | KH11: Valeur obj. | KN11: Prod. | KO11: Valeur obj. | KU11: Prod. | KV11: Valeur obj. | LB11: Prod. | LC11: Valeur obj. | LI11: Prod. | LJ11: Valeur obj. | LP11: Prod. | LQ11: Valeur obj. | LW11: Prod. | LX11: Valeur obj. | MD11: Prod. | ME11: Valeur obj. | MK11: Prod. | ML11: Valeur obj. | MR11: Prod. | MS11: Valeur obj. | MY11: Prod. | MZ11: Valeur obj. | NF11: Prod. | NG11: Valeur obj. | NM11: Prod. | NN11: Valeur obj.
